{
 "cells": [
  {
   "cell_type": "code",
   "execution_count": 1,
   "metadata": {
    "ExecuteTime": {
     "end_time": "2017-06-02T20:36:47.332977",
     "start_time": "2017-06-02T20:36:46.719962"
    },
    "collapsed": false
   },
   "outputs": [],
   "source": [
    "import telegram\n",
    "from telegram.ext import Updater, CommandHandler, MessageHandler, Filters\n",
    "import logging\n",
    "\n",
    "import matplotlib.image as mp_img\n",
    "import numpy as np "
   ]
  },
  {
   "cell_type": "code",
   "execution_count": 2,
   "metadata": {
    "ExecuteTime": {
     "end_time": "2017-06-02T20:16:11.596739",
     "start_time": "2017-06-02T20:16:11.591428"
    },
    "collapsed": false
   },
   "outputs": [],
   "source": [
    "bot = telegram.Bot(token='395861588:AAHXrGm2bD0VUDnVZLd6P45SzUas0e_SKNI')"
   ]
  },
  {
   "cell_type": "code",
   "execution_count": 3,
   "metadata": {
    "ExecuteTime": {
     "end_time": "2017-06-02T20:16:13.407292",
     "start_time": "2017-06-02T20:16:12.203347"
    },
    "collapsed": false
   },
   "outputs": [
    {
     "name": "stdout",
     "output_type": "stream",
     "text": [
      "{'id': 395861588, 'first_name': 'Neuralmind Bot', 'username': 'NeuralmindBot'}\n"
     ]
    }
   ],
   "source": [
    "print(bot.get_me())"
   ]
  },
  {
   "cell_type": "code",
   "execution_count": 4,
   "metadata": {
    "ExecuteTime": {
     "end_time": "2017-06-02T20:49:36.315583",
     "start_time": "2017-06-02T20:49:36.240152"
    },
    "collapsed": false
   },
   "outputs": [],
   "source": [
    "# Enable logging\n",
    "logging.basicConfig(format='%(asctime)s - %(name)s - %(levelname)s - %(message)s',\n",
    "                    level=logging.INFO)\n",
    "\n",
    "logger = logging.getLogger(__name__)\n",
    "\n",
    "\n",
    "# Define a few command handlers. These usually take the two arguments bot and\n",
    "# update. Error handlers also receive the raised TelegramError object in error.\n",
    "def start(bot, update):\n",
    "    update.message.reply_text('Hi!')\n",
    "\n",
    "\n",
    "def help(bot, update):\n",
    "    update.message.reply_text('Help!')\n",
    "\n",
    "\n",
    "def echo(bot, update):\n",
    "    update.message.reply_text(update.message.text)\n",
    "    print('texto:',update.message.text)\n",
    "\n",
    "def photo(bot, update):\n",
    "    update.message.reply_text('recebi imagem')\n",
    "    for u in update.message.photo[:1]:\n",
    "        print('u:',type(u))\n",
    "        print(u['width'],u['height'],u['file_size'])\n",
    "        file_id = u.file_id\n",
    "        newFile = bot.get_file(file_id)\n",
    "        newFile.download('telegram_img.jpg')\n",
    "        f = mp_img.imread('telegram_img.jpg')\n",
    "        print(f.shape)\n",
    "    update.message.reply_text('image tem tamanho: %s' % (f.shape,))\n",
    "        \n",
    "    print('recebi a imagem')\n",
    "\n",
    "def error(bot, update, error):\n",
    "    logger.warn('Update \"%s\" caused error \"%s\"' % (update, error))\n",
    "\n",
    "\n",
    "def main():\n",
    "    # Create the EventHandler and pass it your bot's token.\n",
    "    updater = Updater(\"395861588:AAHXrGm2bD0VUDnVZLd6P45SzUas0e_SKNI\")\n",
    "\n",
    "    # Get the dispatcher to register handlers\n",
    "    dp = updater.dispatcher\n",
    "\n",
    "    # on different commands - answer in Telegram\n",
    "    dp.add_handler(CommandHandler(\"start\", start))\n",
    "    dp.add_handler(CommandHandler(\"help\", help))\n",
    "    #dp.add_handler(CommandHandler(\"ge))\n",
    "\n",
    "    # on noncommand i.e message - echo the message on Telegram\n",
    "    dp.add_handler(MessageHandler(Filters.text, echo))\n",
    "    dp.add_handler(MessageHandler(Filters.photo, photo))\n",
    "\n",
    "    # log all errors\n",
    "    dp.add_error_handler(error)\n",
    "\n",
    "    # Start the Bot\n",
    "    updater.start_polling()\n",
    "\n",
    "    # Run the bot until you press Ctrl-C or the process receives SIGINT,\n",
    "    # SIGTERM or SIGABRT. This should be used most of the time, since\n",
    "    # start_polling() is non-blocking and will stop the bot gracefully.\n",
    "    try:\n",
    "        updater.idle()\n",
    "    except:\n",
    "        KeyboardInterrupt()"
   ]
  },
  {
   "cell_type": "code",
   "execution_count": null,
   "metadata": {
    "ExecuteTime": {
     "start_time": "2017-06-02T23:49:37.003Z"
    },
    "collapsed": false
   },
   "outputs": [
    {
     "name": "stdout",
     "output_type": "stream",
     "text": [
      "texto: Hi\n",
      "u: <class 'telegram.photosize.PhotoSize'>\n",
      "86 90 1765\n",
      "(90, 86, 3)\n",
      "recebi a imagem\n"
     ]
    },
    {
     "name": "stderr",
     "output_type": "stream",
     "text": [
      "2017-06-05 19:18:42,559 - telegram.ext.updater - ERROR - Error while getting Updates: Timed out\n",
      "/Applications/anaconda3/lib/python3.6/site-packages/ipykernel/__main__.py:37: DeprecationWarning: The 'warn' method is deprecated, use 'warning' instead\n",
      "2017-06-05 19:18:42,560 - __main__ - WARNING - Update \"None\" caused error \"Timed out\"\n",
      "2017-06-05 19:19:03,595 - telegram.vendor.ptb_urllib3.urllib3.connectionpool - WARNING - Retrying (Retry(total=2, connect=None, read=None, redirect=None)) after connection broken by 'ConnectTimeoutError(<telegram.vendor.ptb_urllib3.urllib3.connection.VerifiedHTTPSConnection object at 0x116645fd0>, 'Connection to api.telegram.org timed out. (connect timeout=5.0)')': /bot395861588:AAHXrGm2bD0VUDnVZLd6P45SzUas0e_SKNI/getUpdates\n",
      "2017-06-06 05:14:47,239 - telegram.ext.updater - ERROR - Error while getting Updates: Timed out\n",
      "2017-06-06 05:14:47,241 - __main__ - WARNING - Update \"None\" caused error \"Timed out\"\n",
      "2017-06-06 05:18:26,232 - telegram.ext.updater - ERROR - Error while getting Updates: Timed out\n",
      "2017-06-06 05:18:26,233 - __main__ - WARNING - Update \"None\" caused error \"Timed out\"\n",
      "2017-06-06 07:56:16,370 - telegram.ext.updater - ERROR - Error while getting Updates: Timed out\n",
      "2017-06-06 07:56:16,371 - __main__ - WARNING - Update \"None\" caused error \"Timed out\"\n",
      "2017-06-06 11:16:52,898 - telegram.ext.updater - ERROR - Error while getting Updates: Timed out\n",
      "2017-06-06 11:16:52,899 - __main__ - WARNING - Update \"None\" caused error \"Timed out\"\n",
      "2017-06-06 21:04:46,346 - telegram.ext.updater - ERROR - Error while getting Updates: Timed out\n",
      "2017-06-06 21:04:46,347 - __main__ - WARNING - Update \"None\" caused error \"Timed out\"\n",
      "2017-06-06 23:23:43,426 - telegram.ext.updater - ERROR - Error while getting Updates: Timed out\n",
      "2017-06-06 23:23:43,427 - __main__ - WARNING - Update \"None\" caused error \"Timed out\"\n",
      "2017-06-06 23:24:04,459 - telegram.vendor.ptb_urllib3.urllib3.connectionpool - WARNING - Retrying (Retry(total=2, connect=None, read=None, redirect=None)) after connection broken by 'ConnectTimeoutError(<telegram.vendor.ptb_urllib3.urllib3.connection.VerifiedHTTPSConnection object at 0x1169a3470>, 'Connection to api.telegram.org timed out. (connect timeout=5.0)')': /bot395861588:AAHXrGm2bD0VUDnVZLd6P45SzUas0e_SKNI/getUpdates\n",
      "2017-06-06 23:43:22,163 - telegram.ext.updater - ERROR - Error while getting Updates: Timed out\n",
      "2017-06-06 23:43:22,164 - __main__ - WARNING - Update \"None\" caused error \"Timed out\"\n",
      "2017-06-06 23:46:20,646 - telegram.ext.updater - ERROR - Error while getting Updates: Timed out\n",
      "2017-06-06 23:46:20,647 - __main__ - WARNING - Update \"None\" caused error \"Timed out\"\n",
      "2017-06-06 23:46:22,761 - telegram.ext.updater - ERROR - Error while getting Updates: Invalid server response\n",
      "2017-06-06 23:46:22,762 - __main__ - WARNING - Update \"None\" caused error \"Invalid server response\"\n",
      "2017-06-06 23:46:36,282 - telegram.ext.updater - ERROR - Error while getting Updates: Timed out\n",
      "2017-06-06 23:46:36,283 - __main__ - WARNING - Update \"None\" caused error \"Timed out\"\n",
      "2017-06-06 23:46:51,412 - telegram.ext.updater - ERROR - Error while getting Updates: Timed out\n",
      "2017-06-06 23:46:51,413 - __main__ - WARNING - Update \"None\" caused error \"Timed out\"\n",
      "2017-06-07 00:12:20,072 - telegram.ext.updater - ERROR - Error while getting Updates: Timed out\n",
      "2017-06-07 00:12:20,073 - __main__ - WARNING - Update \"None\" caused error \"Timed out\"\n",
      "2017-06-07 02:03:19,318 - telegram.ext.updater - ERROR - Error while getting Updates: Timed out\n",
      "2017-06-07 02:03:19,319 - __main__ - WARNING - Update \"None\" caused error \"Timed out\"\n",
      "2017-06-07 08:37:49,676 - telegram.ext.updater - ERROR - Error while getting Updates: Timed out\n",
      "2017-06-07 08:37:49,677 - __main__ - WARNING - Update \"None\" caused error \"Timed out\"\n"
     ]
    },
    {
     "name": "stdout",
     "output_type": "stream",
     "text": [
      "texto: Hi\n"
     ]
    },
    {
     "name": "stderr",
     "output_type": "stream",
     "text": [
      "2017-06-08 07:08:21,518 - telegram.ext.updater - ERROR - Error while getting Updates: Timed out\n",
      "2017-06-08 07:08:21,519 - __main__ - WARNING - Update \"None\" caused error \"Timed out\"\n",
      "2017-06-08 07:08:52,533 - telegram.vendor.ptb_urllib3.urllib3.connectionpool - WARNING - Retrying (Retry(total=2, connect=None, read=None, redirect=None)) after connection broken by 'NewConnectionError('<telegram.vendor.ptb_urllib3.urllib3.connection.VerifiedHTTPSConnection object at 0x116754eb8>: Failed to establish a new connection: [Errno 8] nodename nor servname provided, or not known',)': /bot395861588:AAHXrGm2bD0VUDnVZLd6P45SzUas0e_SKNI/getUpdates\n",
      "2017-06-08 16:30:44,459 - telegram.ext.updater - ERROR - Error while getting Updates: Timed out\n",
      "2017-06-08 16:30:44,460 - __main__ - WARNING - Update \"None\" caused error \"Timed out\"\n",
      "2017-06-08 16:31:15,474 - telegram.vendor.ptb_urllib3.urllib3.connectionpool - WARNING - Retrying (Retry(total=2, connect=None, read=None, redirect=None)) after connection broken by 'NewConnectionError('<telegram.vendor.ptb_urllib3.urllib3.connection.VerifiedHTTPSConnection object at 0x116a1c9b0>: Failed to establish a new connection: [Errno 8] nodename nor servname provided, or not known',)': /bot395861588:AAHXrGm2bD0VUDnVZLd6P45SzUas0e_SKNI/getUpdates\n"
     ]
    },
    {
     "name": "stdout",
     "output_type": "stream",
     "text": [
      "texto: Hi\n",
      "texto: H\n",
      "u: <class 'telegram.photosize.PhotoSize'>\n",
      "86 90 1765\n",
      "(90, 86, 3)\n",
      "recebi a imagem\n"
     ]
    },
    {
     "name": "stderr",
     "output_type": "stream",
     "text": [
      "2017-06-09 06:32:57,210 - telegram.ext.updater - ERROR - Error while getting Updates: Timed out\n",
      "2017-06-09 06:32:57,211 - __main__ - WARNING - Update \"None\" caused error \"Timed out\"\n",
      "2017-06-09 08:46:05,808 - telegram.ext.updater - ERROR - Error while getting Updates: Timed out\n",
      "2017-06-09 08:46:05,809 - __main__ - WARNING - Update \"None\" caused error \"Timed out\"\n",
      "2017-06-09 18:12:26,787 - telegram.ext.updater - ERROR - Error while getting Updates: Timed out\n",
      "2017-06-09 18:12:26,792 - __main__ - WARNING - Update \"None\" caused error \"Timed out\"\n",
      "2017-06-10 21:06:37,582 - telegram.ext.updater - ERROR - Error while getting Updates: Timed out\n",
      "2017-06-10 21:06:37,583 - __main__ - WARNING - Update \"None\" caused error \"Timed out\"\n",
      "2017-06-10 21:06:58,617 - telegram.vendor.ptb_urllib3.urllib3.connectionpool - WARNING - Retrying (Retry(total=2, connect=None, read=None, redirect=None)) after connection broken by 'ConnectTimeoutError(<telegram.vendor.ptb_urllib3.urllib3.connection.VerifiedHTTPSConnection object at 0x1167545f8>, 'Connection to api.telegram.org timed out. (connect timeout=5.0)')': /bot395861588:AAHXrGm2bD0VUDnVZLd6P45SzUas0e_SKNI/getUpdates\n",
      "2017-06-11 11:12:02,827 - telegram.ext.updater - ERROR - Error while getting Updates: Timed out\n",
      "2017-06-11 11:12:02,828 - __main__ - WARNING - Update \"None\" caused error \"Timed out\"\n",
      "2017-06-11 14:19:15,063 - telegram.ext.updater - ERROR - Error while getting Updates: Timed out\n",
      "2017-06-11 14:19:15,088 - __main__ - WARNING - Update \"None\" caused error \"Timed out\"\n",
      "2017-06-11 14:19:39,264 - telegram.vendor.ptb_urllib3.urllib3.connectionpool - WARNING - Retrying (Retry(total=2, connect=None, read=None, redirect=None)) after connection broken by 'ConnectTimeoutError(<telegram.vendor.ptb_urllib3.urllib3.connection.VerifiedHTTPSConnection object at 0x1169a3eb8>, 'Connection to api.telegram.org timed out. (connect timeout=5.0)')': /bot395861588:AAHXrGm2bD0VUDnVZLd6P45SzUas0e_SKNI/getUpdates\n",
      "2017-06-12 15:47:19,455 - telegram.ext.updater - ERROR - Error while getting Updates: Timed out\n",
      "2017-06-12 15:47:19,460 - __main__ - WARNING - Update \"None\" caused error \"Timed out\"\n",
      "2017-06-12 15:47:33,233 - telegram.ext.updater - ERROR - Error while getting Updates: Timed out\n",
      "2017-06-12 15:47:33,235 - __main__ - WARNING - Update \"None\" caused error \"Timed out\"\n",
      "2017-06-12 15:47:35,679 - telegram.ext.updater - ERROR - Error while getting Updates: Invalid server response\n",
      "2017-06-12 15:47:35,680 - __main__ - WARNING - Update \"None\" caused error \"Invalid server response\"\n",
      "2017-06-12 15:47:38,160 - telegram.ext.updater - ERROR - Error while getting Updates: Invalid server response\n",
      "2017-06-12 15:47:38,161 - __main__ - WARNING - Update \"None\" caused error \"Invalid server response\"\n",
      "2017-06-12 15:47:41,767 - telegram.ext.updater - ERROR - Error while getting Updates: Invalid server response\n",
      "2017-06-12 15:47:41,768 - __main__ - WARNING - Update \"None\" caused error \"Invalid server response\"\n",
      "2017-06-12 15:47:47,056 - telegram.ext.updater - ERROR - Error while getting Updates: Invalid server response\n",
      "2017-06-12 15:47:47,057 - __main__ - WARNING - Update \"None\" caused error \"Invalid server response\"\n",
      "2017-06-12 15:47:54,884 - telegram.ext.updater - ERROR - Error while getting Updates: Invalid server response\n",
      "2017-06-12 15:47:54,886 - __main__ - WARNING - Update \"None\" caused error \"Invalid server response\"\n",
      "2017-06-12 15:48:18,278 - telegram.ext.updater - ERROR - Error while getting Updates: Timed out\n",
      "2017-06-12 15:48:18,279 - __main__ - WARNING - Update \"None\" caused error \"Timed out\"\n",
      "2017-06-12 15:48:48,101 - telegram.ext.updater - ERROR - Error while getting Updates: Timed out\n",
      "2017-06-12 15:48:48,102 - __main__ - WARNING - Update \"None\" caused error \"Timed out\"\n",
      "2017-06-12 15:49:26,422 - telegram.ext.updater - ERROR - Error while getting Updates: Timed out\n",
      "2017-06-12 15:49:26,424 - __main__ - WARNING - Update \"None\" caused error \"Timed out\"\n",
      "2017-06-12 15:50:17,531 - telegram.ext.updater - ERROR - Error while getting Updates: Timed out\n",
      "2017-06-12 15:50:17,532 - __main__ - WARNING - Update \"None\" caused error \"Timed out\"\n",
      "2017-06-12 15:51:00,213 - telegram.ext.updater - ERROR - Error while getting Updates: Timed out\n",
      "2017-06-12 15:51:00,214 - __main__ - WARNING - Update \"None\" caused error \"Timed out\"\n",
      "2017-06-12 15:51:42,942 - telegram.ext.updater - ERROR - Error while getting Updates: Timed out\n",
      "2017-06-12 15:51:42,943 - __main__ - WARNING - Update \"None\" caused error \"Timed out\"\n",
      "2017-06-12 15:52:25,689 - telegram.ext.updater - ERROR - Error while getting Updates: Timed out\n",
      "2017-06-12 15:52:25,690 - __main__ - WARNING - Update \"None\" caused error \"Timed out\"\n",
      "2017-06-12 16:48:57,347 - telegram.ext.updater - ERROR - Error while getting Updates: Timed out\n",
      "2017-06-12 16:48:57,352 - __main__ - WARNING - Update \"None\" caused error \"Timed out\"\n",
      "2017-06-12 22:15:02,515 - telegram.ext.updater - ERROR - Error while getting Updates: Timed out\n",
      "2017-06-12 22:15:02,519 - __main__ - WARNING - Update \"None\" caused error \"Timed out\"\n",
      "2017-06-13 00:48:54,589 - telegram.ext.updater - ERROR - Error while getting Updates: Timed out\n",
      "2017-06-13 00:48:54,590 - __main__ - WARNING - Update \"None\" caused error \"Timed out\"\n",
      "2017-06-13 05:33:54,633 - telegram.ext.updater - ERROR - Error while getting Updates: Timed out\n",
      "2017-06-13 05:33:54,637 - __main__ - WARNING - Update \"None\" caused error \"Timed out\"\n",
      "2017-06-13 06:04:37,642 - telegram.ext.updater - ERROR - Error while getting Updates: Timed out\n",
      "2017-06-13 06:04:37,644 - __main__ - WARNING - Update \"None\" caused error \"Timed out\"\n",
      "2017-06-13 09:12:45,464 - telegram.ext.updater - ERROR - Error while getting Updates: Timed out\n",
      "2017-06-13 09:12:45,465 - __main__ - WARNING - Update \"None\" caused error \"Timed out\"\n",
      "2017-06-13 09:58:26,207 - telegram.ext.updater - ERROR - Error while getting Updates: Timed out\n",
      "2017-06-13 09:58:26,212 - __main__ - WARNING - Update \"None\" caused error \"Timed out\"\n",
      "2017-06-13 23:08:33,690 - telegram.ext.updater - ERROR - Error while getting Updates: Timed out\n",
      "2017-06-13 23:08:33,696 - __main__ - WARNING - Update \"None\" caused error \"Timed out\"\n",
      "2017-06-14 04:58:21,262 - telegram.ext.updater - ERROR - Error while getting Updates: Timed out\n",
      "2017-06-14 04:58:21,321 - __main__ - WARNING - Update \"None\" caused error \"Timed out\"\n",
      "2017-06-14 04:58:42,411 - telegram.vendor.ptb_urllib3.urllib3.connectionpool - WARNING - Retrying (Retry(total=2, connect=None, read=None, redirect=None)) after connection broken by 'ConnectTimeoutError(<telegram.vendor.ptb_urllib3.urllib3.connection.VerifiedHTTPSConnection object at 0x1169a3748>, 'Connection to api.telegram.org timed out. (connect timeout=5.0)')': /bot395861588:AAHXrGm2bD0VUDnVZLd6P45SzUas0e_SKNI/getUpdates\n",
      "2017-06-14 06:13:25,758 - telegram.ext.updater - ERROR - Error while getting Updates: Timed out\n",
      "2017-06-14 06:13:25,759 - __main__ - WARNING - Update \"None\" caused error \"Timed out\"\n",
      "2017-06-14 09:38:33,931 - telegram.ext.updater - ERROR - Error while getting Updates: Timed out\n",
      "2017-06-14 09:38:34,562 - __main__ - WARNING - Update \"None\" caused error \"Timed out\"\n",
      "2017-06-14 17:08:10,854 - telegram.ext.updater - ERROR - Error while getting Updates: Timed out\n",
      "2017-06-14 17:08:12,533 - __main__ - WARNING - Update \"None\" caused error \"Timed out\"\n",
      "2017-06-14 17:08:14,720 - telegram.vendor.ptb_urllib3.urllib3.connectionpool - WARNING - Retrying (Retry(total=2, connect=None, read=None, redirect=None)) after connection broken by 'NewConnectionError('<telegram.vendor.ptb_urllib3.urllib3.connection.VerifiedHTTPSConnection object at 0x1169a3748>: Failed to establish a new connection: [Errno 8] nodename nor servname provided, or not known',)': /bot395861588:AAHXrGm2bD0VUDnVZLd6P45SzUas0e_SKNI/getUpdates\n",
      "2017-06-14 17:08:16,663 - telegram.vendor.ptb_urllib3.urllib3.connectionpool - WARNING - Retrying (Retry(total=1, connect=None, read=None, redirect=None)) after connection broken by 'NewConnectionError('<telegram.vendor.ptb_urllib3.urllib3.connection.VerifiedHTTPSConnection object at 0x1169a3908>: Failed to establish a new connection: [Errno 8] nodename nor servname provided, or not known',)': /bot395861588:AAHXrGm2bD0VUDnVZLd6P45SzUas0e_SKNI/getUpdates\n",
      "2017-06-14 17:08:18,339 - telegram.vendor.ptb_urllib3.urllib3.connectionpool - WARNING - Retrying (Retry(total=0, connect=None, read=None, redirect=None)) after connection broken by 'NewConnectionError('<telegram.vendor.ptb_urllib3.urllib3.connection.VerifiedHTTPSConnection object at 0x116645fd0>: Failed to establish a new connection: [Errno 8] nodename nor servname provided, or not known',)': /bot395861588:AAHXrGm2bD0VUDnVZLd6P45SzUas0e_SKNI/getUpdates\n",
      "2017-06-14 17:08:18,698 - telegram.ext.updater - ERROR - Error while getting Updates: urllib3 HTTPError HTTPSConnectionPool(host='api.telegram.org', port=443): Max retries exceeded with url: /bot395861588:AAHXrGm2bD0VUDnVZLd6P45SzUas0e_SKNI/getUpdates (Caused by NewConnectionError('<telegram.vendor.ptb_urllib3.urllib3.connection.VerifiedHTTPSConnection object at 0x116a1cbe0>: Failed to establish a new connection: [Errno 8] nodename nor servname provided, or not known',))\n",
      "2017-06-14 17:08:19,018 - __main__ - WARNING - Update \"None\" caused error \"urllib3 HTTPError HTTPSConnectionPool(host='api.telegram.org', port=443): Max retries exceeded with url: /bot395861588:AAHXrGm2bD0VUDnVZLd6P45SzUas0e_SKNI/getUpdates (Caused by NewConnectionError('<telegram.vendor.ptb_urllib3.urllib3.connection.VerifiedHTTPSConnection object at 0x116a1cbe0>: Failed to establish a new connection: [Errno 8] nodename nor servname provided, or not known',))\"\n",
      "2017-06-14 17:08:20,488 - telegram.vendor.ptb_urllib3.urllib3.connectionpool - WARNING - Retrying (Retry(total=2, connect=None, read=None, redirect=None)) after connection broken by 'NewConnectionError('<telegram.vendor.ptb_urllib3.urllib3.connection.VerifiedHTTPSConnection object at 0x116a1c7f0>: Failed to establish a new connection: [Errno 8] nodename nor servname provided, or not known',)': /bot395861588:AAHXrGm2bD0VUDnVZLd6P45SzUas0e_SKNI/getUpdates\n",
      "2017-06-14 17:08:20,767 - telegram.vendor.ptb_urllib3.urllib3.connectionpool - WARNING - Retrying (Retry(total=1, connect=None, read=None, redirect=None)) after connection broken by 'NewConnectionError('<telegram.vendor.ptb_urllib3.urllib3.connection.VerifiedHTTPSConnection object at 0x116a1c208>: Failed to establish a new connection: [Errno 8] nodename nor servname provided, or not known',)': /bot395861588:AAHXrGm2bD0VUDnVZLd6P45SzUas0e_SKNI/getUpdates\n",
      "2017-06-14 17:08:20,934 - telegram.vendor.ptb_urllib3.urllib3.connectionpool - WARNING - Retrying (Retry(total=0, connect=None, read=None, redirect=None)) after connection broken by 'NewConnectionError('<telegram.vendor.ptb_urllib3.urllib3.connection.VerifiedHTTPSConnection object at 0x116a1c5c0>: Failed to establish a new connection: [Errno 8] nodename nor servname provided, or not known',)': /bot395861588:AAHXrGm2bD0VUDnVZLd6P45SzUas0e_SKNI/getUpdates\n",
      "2017-06-14 17:08:20,936 - telegram.ext.updater - ERROR - Error while getting Updates: urllib3 HTTPError HTTPSConnectionPool(host='api.telegram.org', port=443): Max retries exceeded with url: /bot395861588:AAHXrGm2bD0VUDnVZLd6P45SzUas0e_SKNI/getUpdates (Caused by NewConnectionError('<telegram.vendor.ptb_urllib3.urllib3.connection.VerifiedHTTPSConnection object at 0x116a1c9b0>: Failed to establish a new connection: [Errno 8] nodename nor servname provided, or not known',))\n",
      "2017-06-14 17:08:21,217 - __main__ - WARNING - Update \"None\" caused error \"urllib3 HTTPError HTTPSConnectionPool(host='api.telegram.org', port=443): Max retries exceeded with url: /bot395861588:AAHXrGm2bD0VUDnVZLd6P45SzUas0e_SKNI/getUpdates (Caused by NewConnectionError('<telegram.vendor.ptb_urllib3.urllib3.connection.VerifiedHTTPSConnection object at 0x116a1c9b0>: Failed to establish a new connection: [Errno 8] nodename nor servname provided, or not known',))\"\n",
      "2017-06-14 17:08:23,471 - telegram.vendor.ptb_urllib3.urllib3.connectionpool - WARNING - Retrying (Retry(total=2, connect=None, read=None, redirect=None)) after connection broken by 'NewConnectionError('<telegram.vendor.ptb_urllib3.urllib3.connection.VerifiedHTTPSConnection object at 0x116a1c860>: Failed to establish a new connection: [Errno 8] nodename nor servname provided, or not known',)': /bot395861588:AAHXrGm2bD0VUDnVZLd6P45SzUas0e_SKNI/getUpdates\n",
      "2017-06-14 17:08:23,472 - telegram.vendor.ptb_urllib3.urllib3.connectionpool - WARNING - Retrying (Retry(total=1, connect=None, read=None, redirect=None)) after connection broken by 'NewConnectionError('<telegram.vendor.ptb_urllib3.urllib3.connection.VerifiedHTTPSConnection object at 0x116a1cef0>: Failed to establish a new connection: [Errno 8] nodename nor servname provided, or not known',)': /bot395861588:AAHXrGm2bD0VUDnVZLd6P45SzUas0e_SKNI/getUpdates\n",
      "2017-06-14 17:08:23,494 - telegram.vendor.ptb_urllib3.urllib3.connectionpool - WARNING - Retrying (Retry(total=0, connect=None, read=None, redirect=None)) after connection broken by 'NewConnectionError('<telegram.vendor.ptb_urllib3.urllib3.connection.VerifiedHTTPSConnection object at 0x116a1c7b8>: Failed to establish a new connection: [Errno 8] nodename nor servname provided, or not known',)': /bot395861588:AAHXrGm2bD0VUDnVZLd6P45SzUas0e_SKNI/getUpdates\n",
      "2017-06-14 17:08:23,496 - telegram.ext.updater - ERROR - Error while getting Updates: urllib3 HTTPError HTTPSConnectionPool(host='api.telegram.org', port=443): Max retries exceeded with url: /bot395861588:AAHXrGm2bD0VUDnVZLd6P45SzUas0e_SKNI/getUpdates (Caused by NewConnectionError('<telegram.vendor.ptb_urllib3.urllib3.connection.VerifiedHTTPSConnection object at 0x116a1c400>: Failed to establish a new connection: [Errno 8] nodename nor servname provided, or not known',))\n",
      "2017-06-14 17:08:23,596 - __main__ - WARNING - Update \"None\" caused error \"urllib3 HTTPError HTTPSConnectionPool(host='api.telegram.org', port=443): Max retries exceeded with url: /bot395861588:AAHXrGm2bD0VUDnVZLd6P45SzUas0e_SKNI/getUpdates (Caused by NewConnectionError('<telegram.vendor.ptb_urllib3.urllib3.connection.VerifiedHTTPSConnection object at 0x116a1c400>: Failed to establish a new connection: [Errno 8] nodename nor servname provided, or not known',))\"\n",
      "2017-06-14 17:08:26,978 - telegram.vendor.ptb_urllib3.urllib3.connectionpool - WARNING - Retrying (Retry(total=2, connect=None, read=None, redirect=None)) after connection broken by 'NewConnectionError('<telegram.vendor.ptb_urllib3.urllib3.connection.VerifiedHTTPSConnection object at 0x116a1c630>: Failed to establish a new connection: [Errno 8] nodename nor servname provided, or not known',)': /bot395861588:AAHXrGm2bD0VUDnVZLd6P45SzUas0e_SKNI/getUpdates\n",
      "2017-06-14 17:08:26,981 - telegram.vendor.ptb_urllib3.urllib3.connectionpool - WARNING - Retrying (Retry(total=1, connect=None, read=None, redirect=None)) after connection broken by 'NewConnectionError('<telegram.vendor.ptb_urllib3.urllib3.connection.VerifiedHTTPSConnection object at 0x1167549b0>: Failed to establish a new connection: [Errno 8] nodename nor servname provided, or not known',)': /bot395861588:AAHXrGm2bD0VUDnVZLd6P45SzUas0e_SKNI/getUpdates\n",
      "2017-06-14 17:08:26,983 - telegram.vendor.ptb_urllib3.urllib3.connectionpool - WARNING - Retrying (Retry(total=0, connect=None, read=None, redirect=None)) after connection broken by 'NewConnectionError('<telegram.vendor.ptb_urllib3.urllib3.connection.VerifiedHTTPSConnection object at 0x110053630>: Failed to establish a new connection: [Errno 8] nodename nor servname provided, or not known',)': /bot395861588:AAHXrGm2bD0VUDnVZLd6P45SzUas0e_SKNI/getUpdates\n",
      "2017-06-14 17:08:27,034 - telegram.ext.updater - ERROR - Error while getting Updates: urllib3 HTTPError HTTPSConnectionPool(host='api.telegram.org', port=443): Max retries exceeded with url: /bot395861588:AAHXrGm2bD0VUDnVZLd6P45SzUas0e_SKNI/getUpdates (Caused by NewConnectionError('<telegram.vendor.ptb_urllib3.urllib3.connection.VerifiedHTTPSConnection object at 0x116754e48>: Failed to establish a new connection: [Errno 8] nodename nor servname provided, or not known',))\n",
      "2017-06-14 17:08:27,035 - __main__ - WARNING - Update \"None\" caused error \"urllib3 HTTPError HTTPSConnectionPool(host='api.telegram.org', port=443): Max retries exceeded with url: /bot395861588:AAHXrGm2bD0VUDnVZLd6P45SzUas0e_SKNI/getUpdates (Caused by NewConnectionError('<telegram.vendor.ptb_urllib3.urllib3.connection.VerifiedHTTPSConnection object at 0x116754e48>: Failed to establish a new connection: [Errno 8] nodename nor servname provided, or not known',))\"\n",
      "2017-06-14 17:08:32,108 - telegram.vendor.ptb_urllib3.urllib3.connectionpool - WARNING - Retrying (Retry(total=2, connect=None, read=None, redirect=None)) after connection broken by 'NewConnectionError('<telegram.vendor.ptb_urllib3.urllib3.connection.VerifiedHTTPSConnection object at 0x1167548d0>: Failed to establish a new connection: [Errno 8] nodename nor servname provided, or not known',)': /bot395861588:AAHXrGm2bD0VUDnVZLd6P45SzUas0e_SKNI/getUpdates\n",
      "2017-06-14 17:08:32,110 - telegram.vendor.ptb_urllib3.urllib3.connectionpool - WARNING - Retrying (Retry(total=1, connect=None, read=None, redirect=None)) after connection broken by 'NewConnectionError('<telegram.vendor.ptb_urllib3.urllib3.connection.VerifiedHTTPSConnection object at 0x116754e10>: Failed to establish a new connection: [Errno 8] nodename nor servname provided, or not known',)': /bot395861588:AAHXrGm2bD0VUDnVZLd6P45SzUas0e_SKNI/getUpdates\n",
      "2017-06-14 17:08:32,165 - telegram.vendor.ptb_urllib3.urllib3.connectionpool - WARNING - Retrying (Retry(total=0, connect=None, read=None, redirect=None)) after connection broken by 'NewConnectionError('<telegram.vendor.ptb_urllib3.urllib3.connection.VerifiedHTTPSConnection object at 0x116a2b0f0>: Failed to establish a new connection: [Errno 8] nodename nor servname provided, or not known',)': /bot395861588:AAHXrGm2bD0VUDnVZLd6P45SzUas0e_SKNI/getUpdates\n",
      "2017-06-14 17:08:32,166 - telegram.ext.updater - ERROR - Error while getting Updates: urllib3 HTTPError HTTPSConnectionPool(host='api.telegram.org', port=443): Max retries exceeded with url: /bot395861588:AAHXrGm2bD0VUDnVZLd6P45SzUas0e_SKNI/getUpdates (Caused by NewConnectionError('<telegram.vendor.ptb_urllib3.urllib3.connection.VerifiedHTTPSConnection object at 0x116a2bb38>: Failed to establish a new connection: [Errno 8] nodename nor servname provided, or not known',))\n",
      "2017-06-14 17:08:32,167 - __main__ - WARNING - Update \"None\" caused error \"urllib3 HTTPError HTTPSConnectionPool(host='api.telegram.org', port=443): Max retries exceeded with url: /bot395861588:AAHXrGm2bD0VUDnVZLd6P45SzUas0e_SKNI/getUpdates (Caused by NewConnectionError('<telegram.vendor.ptb_urllib3.urllib3.connection.VerifiedHTTPSConnection object at 0x116a2bb38>: Failed to establish a new connection: [Errno 8] nodename nor servname provided, or not known',))\"\n",
      "2017-06-14 17:08:39,768 - telegram.vendor.ptb_urllib3.urllib3.connectionpool - WARNING - Retrying (Retry(total=2, connect=None, read=None, redirect=None)) after connection broken by 'NewConnectionError('<telegram.vendor.ptb_urllib3.urllib3.connection.VerifiedHTTPSConnection object at 0x116754cc0>: Failed to establish a new connection: [Errno 8] nodename nor servname provided, or not known',)': /bot395861588:AAHXrGm2bD0VUDnVZLd6P45SzUas0e_SKNI/getUpdates\n",
      "2017-06-14 17:08:39,770 - telegram.vendor.ptb_urllib3.urllib3.connectionpool - WARNING - Retrying (Retry(total=1, connect=None, read=None, redirect=None)) after connection broken by 'NewConnectionError('<telegram.vendor.ptb_urllib3.urllib3.connection.VerifiedHTTPSConnection object at 0x116a35ba8>: Failed to establish a new connection: [Errno 8] nodename nor servname provided, or not known',)': /bot395861588:AAHXrGm2bD0VUDnVZLd6P45SzUas0e_SKNI/getUpdates\n",
      "2017-06-14 17:08:39,771 - telegram.vendor.ptb_urllib3.urllib3.connectionpool - WARNING - Retrying (Retry(total=0, connect=None, read=None, redirect=None)) after connection broken by 'NewConnectionError('<telegram.vendor.ptb_urllib3.urllib3.connection.VerifiedHTTPSConnection object at 0x116a35c18>: Failed to establish a new connection: [Errno 8] nodename nor servname provided, or not known',)': /bot395861588:AAHXrGm2bD0VUDnVZLd6P45SzUas0e_SKNI/getUpdates\n",
      "2017-06-14 17:08:40,044 - telegram.ext.updater - ERROR - Error while getting Updates: urllib3 HTTPError HTTPSConnectionPool(host='api.telegram.org', port=443): Max retries exceeded with url: /bot395861588:AAHXrGm2bD0VUDnVZLd6P45SzUas0e_SKNI/getUpdates (Caused by NewConnectionError('<telegram.vendor.ptb_urllib3.urllib3.connection.VerifiedHTTPSConnection object at 0x1100537b8>: Failed to establish a new connection: [Errno 8] nodename nor servname provided, or not known',))\n",
      "2017-06-14 17:08:40,045 - __main__ - WARNING - Update \"None\" caused error \"urllib3 HTTPError HTTPSConnectionPool(host='api.telegram.org', port=443): Max retries exceeded with url: /bot395861588:AAHXrGm2bD0VUDnVZLd6P45SzUas0e_SKNI/getUpdates (Caused by NewConnectionError('<telegram.vendor.ptb_urllib3.urllib3.connection.VerifiedHTTPSConnection object at 0x1100537b8>: Failed to establish a new connection: [Errno 8] nodename nor servname provided, or not known',))\"\n",
      "2017-06-14 17:08:51,446 - telegram.vendor.ptb_urllib3.urllib3.connectionpool - WARNING - Retrying (Retry(total=2, connect=None, read=None, redirect=None)) after connection broken by 'NewConnectionError('<telegram.vendor.ptb_urllib3.urllib3.connection.VerifiedHTTPSConnection object at 0x116a2bdd8>: Failed to establish a new connection: [Errno 8] nodename nor servname provided, or not known',)': /bot395861588:AAHXrGm2bD0VUDnVZLd6P45SzUas0e_SKNI/getUpdates\n",
      "2017-06-14 17:08:51,447 - telegram.vendor.ptb_urllib3.urllib3.connectionpool - WARNING - Retrying (Retry(total=1, connect=None, read=None, redirect=None)) after connection broken by 'NewConnectionError('<telegram.vendor.ptb_urllib3.urllib3.connection.VerifiedHTTPSConnection object at 0x1167549b0>: Failed to establish a new connection: [Errno 8] nodename nor servname provided, or not known',)': /bot395861588:AAHXrGm2bD0VUDnVZLd6P45SzUas0e_SKNI/getUpdates\n",
      "2017-06-14 17:08:51,675 - telegram.vendor.ptb_urllib3.urllib3.connectionpool - WARNING - Retrying (Retry(total=0, connect=None, read=None, redirect=None)) after connection broken by 'NewConnectionError('<telegram.vendor.ptb_urllib3.urllib3.connection.VerifiedHTTPSConnection object at 0x116a1cef0>: Failed to establish a new connection: [Errno 8] nodename nor servname provided, or not known',)': /bot395861588:AAHXrGm2bD0VUDnVZLd6P45SzUas0e_SKNI/getUpdates\n",
      "2017-06-14 17:08:51,676 - telegram.ext.updater - ERROR - Error while getting Updates: urllib3 HTTPError HTTPSConnectionPool(host='api.telegram.org', port=443): Max retries exceeded with url: /bot395861588:AAHXrGm2bD0VUDnVZLd6P45SzUas0e_SKNI/getUpdates (Caused by NewConnectionError('<telegram.vendor.ptb_urllib3.urllib3.connection.VerifiedHTTPSConnection object at 0x116a1c470>: Failed to establish a new connection: [Errno 8] nodename nor servname provided, or not known',))\n",
      "2017-06-14 17:08:51,677 - __main__ - WARNING - Update \"None\" caused error \"urllib3 HTTPError HTTPSConnectionPool(host='api.telegram.org', port=443): Max retries exceeded with url: /bot395861588:AAHXrGm2bD0VUDnVZLd6P45SzUas0e_SKNI/getUpdates (Caused by NewConnectionError('<telegram.vendor.ptb_urllib3.urllib3.connection.VerifiedHTTPSConnection object at 0x116a1c470>: Failed to establish a new connection: [Errno 8] nodename nor servname provided, or not known',))\"\n",
      "2017-06-14 19:08:54,022 - telegram.vendor.ptb_urllib3.urllib3.connectionpool - WARNING - Retrying (Retry(total=2, connect=None, read=None, redirect=None)) after connection broken by 'NewConnectionError('<telegram.vendor.ptb_urllib3.urllib3.connection.VerifiedHTTPSConnection object at 0x116a2bf60>: Failed to establish a new connection: [Errno 8] nodename nor servname provided, or not known',)': /bot395861588:AAHXrGm2bD0VUDnVZLd6P45SzUas0e_SKNI/getUpdates\n",
      "2017-06-14 19:09:03,370 - telegram.vendor.ptb_urllib3.urllib3.connectionpool - WARNING - Retrying (Retry(total=1, connect=None, read=None, redirect=None)) after connection broken by 'NewConnectionError('<telegram.vendor.ptb_urllib3.urllib3.connection.VerifiedHTTPSConnection object at 0x116a1c9e8>: Failed to establish a new connection: [Errno 8] nodename nor servname provided, or not known',)': /bot395861588:AAHXrGm2bD0VUDnVZLd6P45SzUas0e_SKNI/getUpdates\n",
      "2017-06-14 19:09:03,372 - telegram.vendor.ptb_urllib3.urllib3.connectionpool - WARNING - Retrying (Retry(total=0, connect=None, read=None, redirect=None)) after connection broken by 'NewConnectionError('<telegram.vendor.ptb_urllib3.urllib3.connection.VerifiedHTTPSConnection object at 0x116a1c5f8>: Failed to establish a new connection: [Errno 8] nodename nor servname provided, or not known',)': /bot395861588:AAHXrGm2bD0VUDnVZLd6P45SzUas0e_SKNI/getUpdates\n",
      "2017-06-14 19:09:03,381 - telegram.ext.updater - ERROR - Error while getting Updates: urllib3 HTTPError HTTPSConnectionPool(host='api.telegram.org', port=443): Max retries exceeded with url: /bot395861588:AAHXrGm2bD0VUDnVZLd6P45SzUas0e_SKNI/getUpdates (Caused by NewConnectionError('<telegram.vendor.ptb_urllib3.urllib3.connection.VerifiedHTTPSConnection object at 0x116a1c390>: Failed to establish a new connection: [Errno 8] nodename nor servname provided, or not known',))\n",
      "2017-06-14 19:09:03,385 - __main__ - WARNING - Update \"None\" caused error \"urllib3 HTTPError HTTPSConnectionPool(host='api.telegram.org', port=443): Max retries exceeded with url: /bot395861588:AAHXrGm2bD0VUDnVZLd6P45SzUas0e_SKNI/getUpdates (Caused by NewConnectionError('<telegram.vendor.ptb_urllib3.urllib3.connection.VerifiedHTTPSConnection object at 0x116a1c390>: Failed to establish a new connection: [Errno 8] nodename nor servname provided, or not known',))\"\n",
      "2017-06-14 20:03:32,382 - telegram.ext.updater - ERROR - Error while getting Updates: Timed out\n",
      "2017-06-14 20:03:32,388 - __main__ - WARNING - Update \"None\" caused error \"Timed out\"\n",
      "2017-06-14 20:03:33,391 - telegram.vendor.ptb_urllib3.urllib3.connectionpool - WARNING - Retrying (Retry(total=2, connect=None, read=None, redirect=None)) after connection broken by 'NewConnectionError('<telegram.vendor.ptb_urllib3.urllib3.connection.VerifiedHTTPSConnection object at 0x116a1c780>: Failed to establish a new connection: [Errno 8] nodename nor servname provided, or not known',)': /bot395861588:AAHXrGm2bD0VUDnVZLd6P45SzUas0e_SKNI/getUpdates\n",
      "2017-06-14 20:03:33,393 - telegram.vendor.ptb_urllib3.urllib3.connectionpool - WARNING - Retrying (Retry(total=1, connect=None, read=None, redirect=None)) after connection broken by 'NewConnectionError('<telegram.vendor.ptb_urllib3.urllib3.connection.VerifiedHTTPSConnection object at 0x116a1c470>: Failed to establish a new connection: [Errno 8] nodename nor servname provided, or not known',)': /bot395861588:AAHXrGm2bD0VUDnVZLd6P45SzUas0e_SKNI/getUpdates\n",
      "2017-06-14 20:03:33,394 - telegram.vendor.ptb_urllib3.urllib3.connectionpool - WARNING - Retrying (Retry(total=0, connect=None, read=None, redirect=None)) after connection broken by 'NewConnectionError('<telegram.vendor.ptb_urllib3.urllib3.connection.VerifiedHTTPSConnection object at 0x116a1c320>: Failed to establish a new connection: [Errno 8] nodename nor servname provided, or not known',)': /bot395861588:AAHXrGm2bD0VUDnVZLd6P45SzUas0e_SKNI/getUpdates\n",
      "2017-06-14 20:03:33,396 - telegram.ext.updater - ERROR - Error while getting Updates: urllib3 HTTPError HTTPSConnectionPool(host='api.telegram.org', port=443): Max retries exceeded with url: /bot395861588:AAHXrGm2bD0VUDnVZLd6P45SzUas0e_SKNI/getUpdates (Caused by NewConnectionError('<telegram.vendor.ptb_urllib3.urllib3.connection.VerifiedHTTPSConnection object at 0x1169a37b8>: Failed to establish a new connection: [Errno 8] nodename nor servname provided, or not known',))\n",
      "2017-06-14 20:03:33,500 - __main__ - WARNING - Update \"None\" caused error \"urllib3 HTTPError HTTPSConnectionPool(host='api.telegram.org', port=443): Max retries exceeded with url: /bot395861588:AAHXrGm2bD0VUDnVZLd6P45SzUas0e_SKNI/getUpdates (Caused by NewConnectionError('<telegram.vendor.ptb_urllib3.urllib3.connection.VerifiedHTTPSConnection object at 0x1169a37b8>: Failed to establish a new connection: [Errno 8] nodename nor servname provided, or not known',))\"\n",
      "2017-06-14 20:03:35,025 - telegram.vendor.ptb_urllib3.urllib3.connectionpool - WARNING - Retrying (Retry(total=2, connect=None, read=None, redirect=None)) after connection broken by 'NewConnectionError('<telegram.vendor.ptb_urllib3.urllib3.connection.VerifiedHTTPSConnection object at 0x1169a3b00>: Failed to establish a new connection: [Errno 8] nodename nor servname provided, or not known',)': /bot395861588:AAHXrGm2bD0VUDnVZLd6P45SzUas0e_SKNI/getUpdates\n",
      "2017-06-14 20:03:35,061 - telegram.vendor.ptb_urllib3.urllib3.connectionpool - WARNING - Retrying (Retry(total=1, connect=None, read=None, redirect=None)) after connection broken by 'NewConnectionError('<telegram.vendor.ptb_urllib3.urllib3.connection.VerifiedHTTPSConnection object at 0x1169a3550>: Failed to establish a new connection: [Errno 8] nodename nor servname provided, or not known',)': /bot395861588:AAHXrGm2bD0VUDnVZLd6P45SzUas0e_SKNI/getUpdates\n",
      "2017-06-14 20:03:35,062 - telegram.vendor.ptb_urllib3.urllib3.connectionpool - WARNING - Retrying (Retry(total=0, connect=None, read=None, redirect=None)) after connection broken by 'NewConnectionError('<telegram.vendor.ptb_urllib3.urllib3.connection.VerifiedHTTPSConnection object at 0x1169a3b70>: Failed to establish a new connection: [Errno 8] nodename nor servname provided, or not known',)': /bot395861588:AAHXrGm2bD0VUDnVZLd6P45SzUas0e_SKNI/getUpdates\n",
      "2017-06-14 20:03:35,064 - telegram.ext.updater - ERROR - Error while getting Updates: urllib3 HTTPError HTTPSConnectionPool(host='api.telegram.org', port=443): Max retries exceeded with url: /bot395861588:AAHXrGm2bD0VUDnVZLd6P45SzUas0e_SKNI/getUpdates (Caused by NewConnectionError('<telegram.vendor.ptb_urllib3.urllib3.connection.VerifiedHTTPSConnection object at 0x116a35518>: Failed to establish a new connection: [Errno 8] nodename nor servname provided, or not known',))\n",
      "2017-06-14 20:03:35,065 - __main__ - WARNING - Update \"None\" caused error \"urllib3 HTTPError HTTPSConnectionPool(host='api.telegram.org', port=443): Max retries exceeded with url: /bot395861588:AAHXrGm2bD0VUDnVZLd6P45SzUas0e_SKNI/getUpdates (Caused by NewConnectionError('<telegram.vendor.ptb_urllib3.urllib3.connection.VerifiedHTTPSConnection object at 0x116a35518>: Failed to establish a new connection: [Errno 8] nodename nor servname provided, or not known',))\"\n",
      "2017-06-14 20:03:37,322 - telegram.vendor.ptb_urllib3.urllib3.connectionpool - WARNING - Retrying (Retry(total=2, connect=None, read=None, redirect=None)) after connection broken by 'NewConnectionError('<telegram.vendor.ptb_urllib3.urllib3.connection.VerifiedHTTPSConnection object at 0x1169a3470>: Failed to establish a new connection: [Errno 8] nodename nor servname provided, or not known',)': /bot395861588:AAHXrGm2bD0VUDnVZLd6P45SzUas0e_SKNI/getUpdates\n",
      "2017-06-14 20:03:37,323 - telegram.vendor.ptb_urllib3.urllib3.connectionpool - WARNING - Retrying (Retry(total=1, connect=None, read=None, redirect=None)) after connection broken by 'NewConnectionError('<telegram.vendor.ptb_urllib3.urllib3.connection.VerifiedHTTPSConnection object at 0x116a350b8>: Failed to establish a new connection: [Errno 8] nodename nor servname provided, or not known',)': /bot395861588:AAHXrGm2bD0VUDnVZLd6P45SzUas0e_SKNI/getUpdates\n",
      "2017-06-14 20:03:37,325 - telegram.vendor.ptb_urllib3.urllib3.connectionpool - WARNING - Retrying (Retry(total=0, connect=None, read=None, redirect=None)) after connection broken by 'NewConnectionError('<telegram.vendor.ptb_urllib3.urllib3.connection.VerifiedHTTPSConnection object at 0x116a354e0>: Failed to establish a new connection: [Errno 8] nodename nor servname provided, or not known',)': /bot395861588:AAHXrGm2bD0VUDnVZLd6P45SzUas0e_SKNI/getUpdates\n",
      "2017-06-14 20:03:37,326 - telegram.ext.updater - ERROR - Error while getting Updates: urllib3 HTTPError HTTPSConnectionPool(host='api.telegram.org', port=443): Max retries exceeded with url: /bot395861588:AAHXrGm2bD0VUDnVZLd6P45SzUas0e_SKNI/getUpdates (Caused by NewConnectionError('<telegram.vendor.ptb_urllib3.urllib3.connection.VerifiedHTTPSConnection object at 0x116a35cf8>: Failed to establish a new connection: [Errno 8] nodename nor servname provided, or not known',))\n",
      "2017-06-14 20:03:37,327 - __main__ - WARNING - Update \"None\" caused error \"urllib3 HTTPError HTTPSConnectionPool(host='api.telegram.org', port=443): Max retries exceeded with url: /bot395861588:AAHXrGm2bD0VUDnVZLd6P45SzUas0e_SKNI/getUpdates (Caused by NewConnectionError('<telegram.vendor.ptb_urllib3.urllib3.connection.VerifiedHTTPSConnection object at 0x116a35cf8>: Failed to establish a new connection: [Errno 8] nodename nor servname provided, or not known',))\"\n",
      "2017-06-14 20:03:40,706 - telegram.vendor.ptb_urllib3.urllib3.connectionpool - WARNING - Retrying (Retry(total=2, connect=None, read=None, redirect=None)) after connection broken by 'NewConnectionError('<telegram.vendor.ptb_urllib3.urllib3.connection.VerifiedHTTPSConnection object at 0x116a35710>: Failed to establish a new connection: [Errno 8] nodename nor servname provided, or not known',)': /bot395861588:AAHXrGm2bD0VUDnVZLd6P45SzUas0e_SKNI/getUpdates\n",
      "2017-06-14 20:03:40,707 - telegram.vendor.ptb_urllib3.urllib3.connectionpool - WARNING - Retrying (Retry(total=1, connect=None, read=None, redirect=None)) after connection broken by 'NewConnectionError('<telegram.vendor.ptb_urllib3.urllib3.connection.VerifiedHTTPSConnection object at 0x116a35dd8>: Failed to establish a new connection: [Errno 8] nodename nor servname provided, or not known',)': /bot395861588:AAHXrGm2bD0VUDnVZLd6P45SzUas0e_SKNI/getUpdates\n",
      "2017-06-14 20:03:40,835 - telegram.vendor.ptb_urllib3.urllib3.connectionpool - WARNING - Retrying (Retry(total=0, connect=None, read=None, redirect=None)) after connection broken by 'NewConnectionError('<telegram.vendor.ptb_urllib3.urllib3.connection.VerifiedHTTPSConnection object at 0x116a35d68>: Failed to establish a new connection: [Errno 8] nodename nor servname provided, or not known',)': /bot395861588:AAHXrGm2bD0VUDnVZLd6P45SzUas0e_SKNI/getUpdates\n",
      "2017-06-14 20:03:40,845 - telegram.ext.updater - ERROR - Error while getting Updates: urllib3 HTTPError HTTPSConnectionPool(host='api.telegram.org', port=443): Max retries exceeded with url: /bot395861588:AAHXrGm2bD0VUDnVZLd6P45SzUas0e_SKNI/getUpdates (Caused by NewConnectionError('<telegram.vendor.ptb_urllib3.urllib3.connection.VerifiedHTTPSConnection object at 0x116a35fd0>: Failed to establish a new connection: [Errno 8] nodename nor servname provided, or not known',))\n",
      "2017-06-14 20:03:40,846 - __main__ - WARNING - Update \"None\" caused error \"urllib3 HTTPError HTTPSConnectionPool(host='api.telegram.org', port=443): Max retries exceeded with url: /bot395861588:AAHXrGm2bD0VUDnVZLd6P45SzUas0e_SKNI/getUpdates (Caused by NewConnectionError('<telegram.vendor.ptb_urllib3.urllib3.connection.VerifiedHTTPSConnection object at 0x116a35fd0>: Failed to establish a new connection: [Errno 8] nodename nor servname provided, or not known',))\"\n",
      "2017-06-14 20:03:45,911 - telegram.vendor.ptb_urllib3.urllib3.connectionpool - WARNING - Retrying (Retry(total=2, connect=None, read=None, redirect=None)) after connection broken by 'NewConnectionError('<telegram.vendor.ptb_urllib3.urllib3.connection.VerifiedHTTPSConnection object at 0x116a35208>: Failed to establish a new connection: [Errno 8] nodename nor servname provided, or not known',)': /bot395861588:AAHXrGm2bD0VUDnVZLd6P45SzUas0e_SKNI/getUpdates\n",
      "2017-06-14 20:03:45,912 - telegram.vendor.ptb_urllib3.urllib3.connectionpool - WARNING - Retrying (Retry(total=1, connect=None, read=None, redirect=None)) after connection broken by 'NewConnectionError('<telegram.vendor.ptb_urllib3.urllib3.connection.VerifiedHTTPSConnection object at 0x1169a3828>: Failed to establish a new connection: [Errno 8] nodename nor servname provided, or not known',)': /bot395861588:AAHXrGm2bD0VUDnVZLd6P45SzUas0e_SKNI/getUpdates\n",
      "2017-06-14 20:03:45,913 - telegram.vendor.ptb_urllib3.urllib3.connectionpool - WARNING - Retrying (Retry(total=0, connect=None, read=None, redirect=None)) after connection broken by 'NewConnectionError('<telegram.vendor.ptb_urllib3.urllib3.connection.VerifiedHTTPSConnection object at 0x116645fd0>: Failed to establish a new connection: [Errno 8] nodename nor servname provided, or not known',)': /bot395861588:AAHXrGm2bD0VUDnVZLd6P45SzUas0e_SKNI/getUpdates\n",
      "2017-06-14 20:03:45,915 - telegram.ext.updater - ERROR - Error while getting Updates: urllib3 HTTPError HTTPSConnectionPool(host='api.telegram.org', port=443): Max retries exceeded with url: /bot395861588:AAHXrGm2bD0VUDnVZLd6P45SzUas0e_SKNI/getUpdates (Caused by NewConnectionError('<telegram.vendor.ptb_urllib3.urllib3.connection.VerifiedHTTPSConnection object at 0x116995eb8>: Failed to establish a new connection: [Errno 8] nodename nor servname provided, or not known',))\n",
      "2017-06-14 20:03:45,916 - __main__ - WARNING - Update \"None\" caused error \"urllib3 HTTPError HTTPSConnectionPool(host='api.telegram.org', port=443): Max retries exceeded with url: /bot395861588:AAHXrGm2bD0VUDnVZLd6P45SzUas0e_SKNI/getUpdates (Caused by NewConnectionError('<telegram.vendor.ptb_urllib3.urllib3.connection.VerifiedHTTPSConnection object at 0x116995eb8>: Failed to establish a new connection: [Errno 8] nodename nor servname provided, or not known',))\"\n",
      "2017-06-14 20:03:53,520 - telegram.vendor.ptb_urllib3.urllib3.connectionpool - WARNING - Retrying (Retry(total=2, connect=None, read=None, redirect=None)) after connection broken by 'NewConnectionError('<telegram.vendor.ptb_urllib3.urllib3.connection.VerifiedHTTPSConnection object at 0x116a359e8>: Failed to establish a new connection: [Errno 8] nodename nor servname provided, or not known',)': /bot395861588:AAHXrGm2bD0VUDnVZLd6P45SzUas0e_SKNI/getUpdates\n",
      "2017-06-14 20:03:53,522 - telegram.vendor.ptb_urllib3.urllib3.connectionpool - WARNING - Retrying (Retry(total=1, connect=None, read=None, redirect=None)) after connection broken by 'NewConnectionError('<telegram.vendor.ptb_urllib3.urllib3.connection.VerifiedHTTPSConnection object at 0x1169a31d0>: Failed to establish a new connection: [Errno 8] nodename nor servname provided, or not known',)': /bot395861588:AAHXrGm2bD0VUDnVZLd6P45SzUas0e_SKNI/getUpdates\n",
      "2017-06-14 20:03:53,523 - telegram.vendor.ptb_urllib3.urllib3.connectionpool - WARNING - Retrying (Retry(total=0, connect=None, read=None, redirect=None)) after connection broken by 'NewConnectionError('<telegram.vendor.ptb_urllib3.urllib3.connection.VerifiedHTTPSConnection object at 0x1169a34e0>: Failed to establish a new connection: [Errno 8] nodename nor servname provided, or not known',)': /bot395861588:AAHXrGm2bD0VUDnVZLd6P45SzUas0e_SKNI/getUpdates\n",
      "2017-06-14 20:03:53,525 - telegram.ext.updater - ERROR - Error while getting Updates: urllib3 HTTPError HTTPSConnectionPool(host='api.telegram.org', port=443): Max retries exceeded with url: /bot395861588:AAHXrGm2bD0VUDnVZLd6P45SzUas0e_SKNI/getUpdates (Caused by NewConnectionError('<telegram.vendor.ptb_urllib3.urllib3.connection.VerifiedHTTPSConnection object at 0x1169a3550>: Failed to establish a new connection: [Errno 8] nodename nor servname provided, or not known',))\n",
      "2017-06-14 20:03:53,526 - __main__ - WARNING - Update \"None\" caused error \"urllib3 HTTPError HTTPSConnectionPool(host='api.telegram.org', port=443): Max retries exceeded with url: /bot395861588:AAHXrGm2bD0VUDnVZLd6P45SzUas0e_SKNI/getUpdates (Caused by NewConnectionError('<telegram.vendor.ptb_urllib3.urllib3.connection.VerifiedHTTPSConnection object at 0x1169a3550>: Failed to establish a new connection: [Errno 8] nodename nor servname provided, or not known',))\"\n",
      "2017-06-14 20:58:06,653 - telegram.ext.updater - ERROR - Error while getting Updates: Timed out\n",
      "2017-06-14 20:58:06,657 - __main__ - WARNING - Update \"None\" caused error \"Timed out\"\n",
      "2017-06-14 20:58:09,754 - telegram.vendor.ptb_urllib3.urllib3.connectionpool - WARNING - Retrying (Retry(total=2, connect=None, read=None, redirect=None)) after connection broken by 'NewConnectionError('<telegram.vendor.ptb_urllib3.urllib3.connection.VerifiedHTTPSConnection object at 0x116a1c780>: Failed to establish a new connection: [Errno 8] nodename nor servname provided, or not known',)': /bot395861588:AAHXrGm2bD0VUDnVZLd6P45SzUas0e_SKNI/getUpdates\n",
      "2017-06-14 20:58:09,789 - telegram.vendor.ptb_urllib3.urllib3.connectionpool - WARNING - Retrying (Retry(total=1, connect=None, read=None, redirect=None)) after connection broken by 'NewConnectionError('<telegram.vendor.ptb_urllib3.urllib3.connection.VerifiedHTTPSConnection object at 0x116a1c470>: Failed to establish a new connection: [Errno 8] nodename nor servname provided, or not known',)': /bot395861588:AAHXrGm2bD0VUDnVZLd6P45SzUas0e_SKNI/getUpdates\n",
      "2017-06-14 20:58:09,792 - telegram.vendor.ptb_urllib3.urllib3.connectionpool - WARNING - Retrying (Retry(total=0, connect=None, read=None, redirect=None)) after connection broken by 'NewConnectionError('<telegram.vendor.ptb_urllib3.urllib3.connection.VerifiedHTTPSConnection object at 0x116a1c978>: Failed to establish a new connection: [Errno 8] nodename nor servname provided, or not known',)': /bot395861588:AAHXrGm2bD0VUDnVZLd6P45SzUas0e_SKNI/getUpdates\n",
      "2017-06-14 20:58:09,794 - telegram.ext.updater - ERROR - Error while getting Updates: urllib3 HTTPError HTTPSConnectionPool(host='api.telegram.org', port=443): Max retries exceeded with url: /bot395861588:AAHXrGm2bD0VUDnVZLd6P45SzUas0e_SKNI/getUpdates (Caused by NewConnectionError('<telegram.vendor.ptb_urllib3.urllib3.connection.VerifiedHTTPSConnection object at 0x116a1cba8>: Failed to establish a new connection: [Errno 8] nodename nor servname provided, or not known',))\n",
      "2017-06-14 20:58:09,796 - __main__ - WARNING - Update \"None\" caused error \"urllib3 HTTPError HTTPSConnectionPool(host='api.telegram.org', port=443): Max retries exceeded with url: /bot395861588:AAHXrGm2bD0VUDnVZLd6P45SzUas0e_SKNI/getUpdates (Caused by NewConnectionError('<telegram.vendor.ptb_urllib3.urllib3.connection.VerifiedHTTPSConnection object at 0x116a1cba8>: Failed to establish a new connection: [Errno 8] nodename nor servname provided, or not known',))\"\n",
      "2017-06-14 20:58:11,310 - telegram.vendor.ptb_urllib3.urllib3.connectionpool - WARNING - Retrying (Retry(total=2, connect=None, read=None, redirect=None)) after connection broken by 'NewConnectionError('<telegram.vendor.ptb_urllib3.urllib3.connection.VerifiedHTTPSConnection object at 0x116754828>: Failed to establish a new connection: [Errno 8] nodename nor servname provided, or not known',)': /bot395861588:AAHXrGm2bD0VUDnVZLd6P45SzUas0e_SKNI/getUpdates\n",
      "2017-06-14 20:58:11,432 - telegram.vendor.ptb_urllib3.urllib3.connectionpool - WARNING - Retrying (Retry(total=1, connect=None, read=None, redirect=None)) after connection broken by 'NewConnectionError('<telegram.vendor.ptb_urllib3.urllib3.connection.VerifiedHTTPSConnection object at 0x116a1c7b8>: Failed to establish a new connection: [Errno 8] nodename nor servname provided, or not known',)': /bot395861588:AAHXrGm2bD0VUDnVZLd6P45SzUas0e_SKNI/getUpdates\n",
      "2017-06-14 20:58:11,434 - telegram.vendor.ptb_urllib3.urllib3.connectionpool - WARNING - Retrying (Retry(total=0, connect=None, read=None, redirect=None)) after connection broken by 'NewConnectionError('<telegram.vendor.ptb_urllib3.urllib3.connection.VerifiedHTTPSConnection object at 0x116a1c4a8>: Failed to establish a new connection: [Errno 8] nodename nor servname provided, or not known',)': /bot395861588:AAHXrGm2bD0VUDnVZLd6P45SzUas0e_SKNI/getUpdates\n",
      "2017-06-14 20:58:11,435 - telegram.ext.updater - ERROR - Error while getting Updates: urllib3 HTTPError HTTPSConnectionPool(host='api.telegram.org', port=443): Max retries exceeded with url: /bot395861588:AAHXrGm2bD0VUDnVZLd6P45SzUas0e_SKNI/getUpdates (Caused by NewConnectionError('<telegram.vendor.ptb_urllib3.urllib3.connection.VerifiedHTTPSConnection object at 0x116a2bb38>: Failed to establish a new connection: [Errno 8] nodename nor servname provided, or not known',))\n",
      "2017-06-14 20:58:11,437 - __main__ - WARNING - Update \"None\" caused error \"urllib3 HTTPError HTTPSConnectionPool(host='api.telegram.org', port=443): Max retries exceeded with url: /bot395861588:AAHXrGm2bD0VUDnVZLd6P45SzUas0e_SKNI/getUpdates (Caused by NewConnectionError('<telegram.vendor.ptb_urllib3.urllib3.connection.VerifiedHTTPSConnection object at 0x116a2bb38>: Failed to establish a new connection: [Errno 8] nodename nor servname provided, or not known',))\"\n",
      "2017-06-14 20:58:13,702 - telegram.vendor.ptb_urllib3.urllib3.connectionpool - WARNING - Retrying (Retry(total=2, connect=None, read=None, redirect=None)) after connection broken by 'NewConnectionError('<telegram.vendor.ptb_urllib3.urllib3.connection.VerifiedHTTPSConnection object at 0x116754470>: Failed to establish a new connection: [Errno 8] nodename nor servname provided, or not known',)': /bot395861588:AAHXrGm2bD0VUDnVZLd6P45SzUas0e_SKNI/getUpdates\n",
      "2017-06-14 20:58:13,713 - telegram.vendor.ptb_urllib3.urllib3.connectionpool - WARNING - Retrying (Retry(total=1, connect=None, read=None, redirect=None)) after connection broken by 'NewConnectionError('<telegram.vendor.ptb_urllib3.urllib3.connection.VerifiedHTTPSConnection object at 0x116a50160>: Failed to establish a new connection: [Errno 8] nodename nor servname provided, or not known',)': /bot395861588:AAHXrGm2bD0VUDnVZLd6P45SzUas0e_SKNI/getUpdates\n",
      "2017-06-14 20:58:13,715 - telegram.vendor.ptb_urllib3.urllib3.connectionpool - WARNING - Retrying (Retry(total=0, connect=None, read=None, redirect=None)) after connection broken by 'NewConnectionError('<telegram.vendor.ptb_urllib3.urllib3.connection.VerifiedHTTPSConnection object at 0x116a500b8>: Failed to establish a new connection: [Errno 8] nodename nor servname provided, or not known',)': /bot395861588:AAHXrGm2bD0VUDnVZLd6P45SzUas0e_SKNI/getUpdates\n",
      "2017-06-14 20:58:13,717 - telegram.ext.updater - ERROR - Error while getting Updates: urllib3 HTTPError HTTPSConnectionPool(host='api.telegram.org', port=443): Max retries exceeded with url: /bot395861588:AAHXrGm2bD0VUDnVZLd6P45SzUas0e_SKNI/getUpdates (Caused by NewConnectionError('<telegram.vendor.ptb_urllib3.urllib3.connection.VerifiedHTTPSConnection object at 0x116a503c8>: Failed to establish a new connection: [Errno 8] nodename nor servname provided, or not known',))\n",
      "2017-06-14 20:58:13,721 - __main__ - WARNING - Update \"None\" caused error \"urllib3 HTTPError HTTPSConnectionPool(host='api.telegram.org', port=443): Max retries exceeded with url: /bot395861588:AAHXrGm2bD0VUDnVZLd6P45SzUas0e_SKNI/getUpdates (Caused by NewConnectionError('<telegram.vendor.ptb_urllib3.urllib3.connection.VerifiedHTTPSConnection object at 0x116a503c8>: Failed to establish a new connection: [Errno 8] nodename nor servname provided, or not known',))\"\n",
      "2017-06-14 20:58:17,102 - telegram.vendor.ptb_urllib3.urllib3.connectionpool - WARNING - Retrying (Retry(total=2, connect=None, read=None, redirect=None)) after connection broken by 'NewConnectionError('<telegram.vendor.ptb_urllib3.urllib3.connection.VerifiedHTTPSConnection object at 0x116a50240>: Failed to establish a new connection: [Errno 8] nodename nor servname provided, or not known',)': /bot395861588:AAHXrGm2bD0VUDnVZLd6P45SzUas0e_SKNI/getUpdates\n",
      "2017-06-14 20:58:17,115 - telegram.vendor.ptb_urllib3.urllib3.connectionpool - WARNING - Retrying (Retry(total=1, connect=None, read=None, redirect=None)) after connection broken by 'NewConnectionError('<telegram.vendor.ptb_urllib3.urllib3.connection.VerifiedHTTPSConnection object at 0x116a50470>: Failed to establish a new connection: [Errno 8] nodename nor servname provided, or not known',)': /bot395861588:AAHXrGm2bD0VUDnVZLd6P45SzUas0e_SKNI/getUpdates\n",
      "2017-06-14 20:58:17,197 - telegram.vendor.ptb_urllib3.urllib3.connectionpool - WARNING - Retrying (Retry(total=0, connect=None, read=None, redirect=None)) after connection broken by 'NewConnectionError('<telegram.vendor.ptb_urllib3.urllib3.connection.VerifiedHTTPSConnection object at 0x116a50550>: Failed to establish a new connection: [Errno 8] nodename nor servname provided, or not known',)': /bot395861588:AAHXrGm2bD0VUDnVZLd6P45SzUas0e_SKNI/getUpdates\n",
      "2017-06-14 20:58:17,216 - telegram.ext.updater - ERROR - Error while getting Updates: urllib3 HTTPError HTTPSConnectionPool(host='api.telegram.org', port=443): Max retries exceeded with url: /bot395861588:AAHXrGm2bD0VUDnVZLd6P45SzUas0e_SKNI/getUpdates (Caused by NewConnectionError('<telegram.vendor.ptb_urllib3.urllib3.connection.VerifiedHTTPSConnection object at 0x116a50748>: Failed to establish a new connection: [Errno 8] nodename nor servname provided, or not known',))\n",
      "2017-06-14 20:58:17,217 - __main__ - WARNING - Update \"None\" caused error \"urllib3 HTTPError HTTPSConnectionPool(host='api.telegram.org', port=443): Max retries exceeded with url: /bot395861588:AAHXrGm2bD0VUDnVZLd6P45SzUas0e_SKNI/getUpdates (Caused by NewConnectionError('<telegram.vendor.ptb_urllib3.urllib3.connection.VerifiedHTTPSConnection object at 0x116a50748>: Failed to establish a new connection: [Errno 8] nodename nor servname provided, or not known',))\"\n",
      "2017-06-14 20:58:22,286 - telegram.vendor.ptb_urllib3.urllib3.connectionpool - WARNING - Retrying (Retry(total=2, connect=None, read=None, redirect=None)) after connection broken by 'NewConnectionError('<telegram.vendor.ptb_urllib3.urllib3.connection.VerifiedHTTPSConnection object at 0x1167540f0>: Failed to establish a new connection: [Errno 8] nodename nor servname provided, or not known',)': /bot395861588:AAHXrGm2bD0VUDnVZLd6P45SzUas0e_SKNI/getUpdates\n",
      "2017-06-14 20:58:22,292 - telegram.vendor.ptb_urllib3.urllib3.connectionpool - WARNING - Retrying (Retry(total=1, connect=None, read=None, redirect=None)) after connection broken by 'NewConnectionError('<telegram.vendor.ptb_urllib3.urllib3.connection.VerifiedHTTPSConnection object at 0x116754828>: Failed to establish a new connection: [Errno 8] nodename nor servname provided, or not known',)': /bot395861588:AAHXrGm2bD0VUDnVZLd6P45SzUas0e_SKNI/getUpdates\n",
      "2017-06-14 20:58:22,294 - telegram.vendor.ptb_urllib3.urllib3.connectionpool - WARNING - Retrying (Retry(total=0, connect=None, read=None, redirect=None)) after connection broken by 'NewConnectionError('<telegram.vendor.ptb_urllib3.urllib3.connection.VerifiedHTTPSConnection object at 0x116a1c4a8>: Failed to establish a new connection: [Errno 8] nodename nor servname provided, or not known',)': /bot395861588:AAHXrGm2bD0VUDnVZLd6P45SzUas0e_SKNI/getUpdates\n",
      "2017-06-14 20:58:22,296 - telegram.ext.updater - ERROR - Error while getting Updates: urllib3 HTTPError HTTPSConnectionPool(host='api.telegram.org', port=443): Max retries exceeded with url: /bot395861588:AAHXrGm2bD0VUDnVZLd6P45SzUas0e_SKNI/getUpdates (Caused by NewConnectionError('<telegram.vendor.ptb_urllib3.urllib3.connection.VerifiedHTTPSConnection object at 0x116a1c978>: Failed to establish a new connection: [Errno 8] nodename nor servname provided, or not known',))\n",
      "2017-06-14 20:58:22,297 - __main__ - WARNING - Update \"None\" caused error \"urllib3 HTTPError HTTPSConnectionPool(host='api.telegram.org', port=443): Max retries exceeded with url: /bot395861588:AAHXrGm2bD0VUDnVZLd6P45SzUas0e_SKNI/getUpdates (Caused by NewConnectionError('<telegram.vendor.ptb_urllib3.urllib3.connection.VerifiedHTTPSConnection object at 0x116a1c978>: Failed to establish a new connection: [Errno 8] nodename nor servname provided, or not known',))\"\n",
      "2017-06-14 20:58:29,902 - telegram.vendor.ptb_urllib3.urllib3.connectionpool - WARNING - Retrying (Retry(total=2, connect=None, read=None, redirect=None)) after connection broken by 'NewConnectionError('<telegram.vendor.ptb_urllib3.urllib3.connection.VerifiedHTTPSConnection object at 0x116a1cbe0>: Failed to establish a new connection: [Errno 8] nodename nor servname provided, or not known',)': /bot395861588:AAHXrGm2bD0VUDnVZLd6P45SzUas0e_SKNI/getUpdates\n",
      "2017-06-14 20:58:29,938 - telegram.vendor.ptb_urllib3.urllib3.connectionpool - WARNING - Retrying (Retry(total=1, connect=None, read=None, redirect=None)) after connection broken by 'NewConnectionError('<telegram.vendor.ptb_urllib3.urllib3.connection.VerifiedHTTPSConnection object at 0x116a1ce48>: Failed to establish a new connection: [Errno 8] nodename nor servname provided, or not known',)': /bot395861588:AAHXrGm2bD0VUDnVZLd6P45SzUas0e_SKNI/getUpdates\n",
      "2017-06-14 20:58:29,940 - telegram.vendor.ptb_urllib3.urllib3.connectionpool - WARNING - Retrying (Retry(total=0, connect=None, read=None, redirect=None)) after connection broken by 'NewConnectionError('<telegram.vendor.ptb_urllib3.urllib3.connection.VerifiedHTTPSConnection object at 0x1100537b8>: Failed to establish a new connection: [Errno 8] nodename nor servname provided, or not known',)': /bot395861588:AAHXrGm2bD0VUDnVZLd6P45SzUas0e_SKNI/getUpdates\n",
      "2017-06-14 20:58:29,942 - telegram.ext.updater - ERROR - Error while getting Updates: urllib3 HTTPError HTTPSConnectionPool(host='api.telegram.org', port=443): Max retries exceeded with url: /bot395861588:AAHXrGm2bD0VUDnVZLd6P45SzUas0e_SKNI/getUpdates (Caused by NewConnectionError('<telegram.vendor.ptb_urllib3.urllib3.connection.VerifiedHTTPSConnection object at 0x116a1cc88>: Failed to establish a new connection: [Errno 8] nodename nor servname provided, or not known',))\n",
      "2017-06-14 20:58:29,946 - __main__ - WARNING - Update \"None\" caused error \"urllib3 HTTPError HTTPSConnectionPool(host='api.telegram.org', port=443): Max retries exceeded with url: /bot395861588:AAHXrGm2bD0VUDnVZLd6P45SzUas0e_SKNI/getUpdates (Caused by NewConnectionError('<telegram.vendor.ptb_urllib3.urllib3.connection.VerifiedHTTPSConnection object at 0x116a1cc88>: Failed to establish a new connection: [Errno 8] nodename nor servname provided, or not known',))\"\n",
      "2017-06-14 21:52:41,635 - telegram.ext.updater - ERROR - Error while getting Updates: Timed out\n",
      "2017-06-14 21:52:41,640 - __main__ - WARNING - Update \"None\" caused error \"Timed out\"\n",
      "2017-06-14 21:52:48,372 - telegram.vendor.ptb_urllib3.urllib3.connectionpool - WARNING - Retrying (Retry(total=2, connect=None, read=None, redirect=None)) after connection broken by 'NewConnectionError('<telegram.vendor.ptb_urllib3.urllib3.connection.VerifiedHTTPSConnection object at 0x116a1c710>: Failed to establish a new connection: [Errno 8] nodename nor servname provided, or not known',)': /bot395861588:AAHXrGm2bD0VUDnVZLd6P45SzUas0e_SKNI/getUpdates\n",
      "2017-06-14 21:52:48,397 - telegram.vendor.ptb_urllib3.urllib3.connectionpool - WARNING - Retrying (Retry(total=1, connect=None, read=None, redirect=None)) after connection broken by 'NewConnectionError('<telegram.vendor.ptb_urllib3.urllib3.connection.VerifiedHTTPSConnection object at 0x1169a31d0>: Failed to establish a new connection: [Errno 8] nodename nor servname provided, or not known',)': /bot395861588:AAHXrGm2bD0VUDnVZLd6P45SzUas0e_SKNI/getUpdates\n",
      "2017-06-14 21:52:48,405 - telegram.vendor.ptb_urllib3.urllib3.connectionpool - WARNING - Retrying (Retry(total=0, connect=None, read=None, redirect=None)) after connection broken by 'NewConnectionError('<telegram.vendor.ptb_urllib3.urllib3.connection.VerifiedHTTPSConnection object at 0x1169a3ba8>: Failed to establish a new connection: [Errno 8] nodename nor servname provided, or not known',)': /bot395861588:AAHXrGm2bD0VUDnVZLd6P45SzUas0e_SKNI/getUpdates\n",
      "2017-06-14 21:52:48,408 - telegram.ext.updater - ERROR - Error while getting Updates: urllib3 HTTPError HTTPSConnectionPool(host='api.telegram.org', port=443): Max retries exceeded with url: /bot395861588:AAHXrGm2bD0VUDnVZLd6P45SzUas0e_SKNI/getUpdates (Caused by NewConnectionError('<telegram.vendor.ptb_urllib3.urllib3.connection.VerifiedHTTPSConnection object at 0x1169a3b70>: Failed to establish a new connection: [Errno 8] nodename nor servname provided, or not known',))\n",
      "2017-06-14 21:52:48,410 - __main__ - WARNING - Update \"None\" caused error \"urllib3 HTTPError HTTPSConnectionPool(host='api.telegram.org', port=443): Max retries exceeded with url: /bot395861588:AAHXrGm2bD0VUDnVZLd6P45SzUas0e_SKNI/getUpdates (Caused by NewConnectionError('<telegram.vendor.ptb_urllib3.urllib3.connection.VerifiedHTTPSConnection object at 0x1169a3b70>: Failed to establish a new connection: [Errno 8] nodename nor servname provided, or not known',))\"\n",
      "2017-06-14 21:52:49,919 - telegram.vendor.ptb_urllib3.urllib3.connectionpool - WARNING - Retrying (Retry(total=2, connect=None, read=None, redirect=None)) after connection broken by 'NewConnectionError('<telegram.vendor.ptb_urllib3.urllib3.connection.VerifiedHTTPSConnection object at 0x116a35b70>: Failed to establish a new connection: [Errno 8] nodename nor servname provided, or not known',)': /bot395861588:AAHXrGm2bD0VUDnVZLd6P45SzUas0e_SKNI/getUpdates\n",
      "2017-06-14 21:52:49,921 - telegram.vendor.ptb_urllib3.urllib3.connectionpool - WARNING - Retrying (Retry(total=1, connect=None, read=None, redirect=None)) after connection broken by 'NewConnectionError('<telegram.vendor.ptb_urllib3.urllib3.connection.VerifiedHTTPSConnection object at 0x116a35fd0>: Failed to establish a new connection: [Errno 8] nodename nor servname provided, or not known',)': /bot395861588:AAHXrGm2bD0VUDnVZLd6P45SzUas0e_SKNI/getUpdates\n",
      "2017-06-14 21:52:49,923 - telegram.vendor.ptb_urllib3.urllib3.connectionpool - WARNING - Retrying (Retry(total=0, connect=None, read=None, redirect=None)) after connection broken by 'NewConnectionError('<telegram.vendor.ptb_urllib3.urllib3.connection.VerifiedHTTPSConnection object at 0x116a50630>: Failed to establish a new connection: [Errno 8] nodename nor servname provided, or not known',)': /bot395861588:AAHXrGm2bD0VUDnVZLd6P45SzUas0e_SKNI/getUpdates\n",
      "2017-06-14 21:52:49,925 - telegram.ext.updater - ERROR - Error while getting Updates: urllib3 HTTPError HTTPSConnectionPool(host='api.telegram.org', port=443): Max retries exceeded with url: /bot395861588:AAHXrGm2bD0VUDnVZLd6P45SzUas0e_SKNI/getUpdates (Caused by NewConnectionError('<telegram.vendor.ptb_urllib3.urllib3.connection.VerifiedHTTPSConnection object at 0x116a504a8>: Failed to establish a new connection: [Errno 8] nodename nor servname provided, or not known',))\n",
      "2017-06-14 21:52:49,927 - __main__ - WARNING - Update \"None\" caused error \"urllib3 HTTPError HTTPSConnectionPool(host='api.telegram.org', port=443): Max retries exceeded with url: /bot395861588:AAHXrGm2bD0VUDnVZLd6P45SzUas0e_SKNI/getUpdates (Caused by NewConnectionError('<telegram.vendor.ptb_urllib3.urllib3.connection.VerifiedHTTPSConnection object at 0x116a504a8>: Failed to establish a new connection: [Errno 8] nodename nor servname provided, or not known',))\"\n",
      "2017-06-14 21:52:52,179 - telegram.vendor.ptb_urllib3.urllib3.connectionpool - WARNING - Retrying (Retry(total=2, connect=None, read=None, redirect=None)) after connection broken by 'NewConnectionError('<telegram.vendor.ptb_urllib3.urllib3.connection.VerifiedHTTPSConnection object at 0x116a354a8>: Failed to establish a new connection: [Errno 8] nodename nor servname provided, or not known',)': /bot395861588:AAHXrGm2bD0VUDnVZLd6P45SzUas0e_SKNI/getUpdates\n",
      "2017-06-14 21:52:52,180 - telegram.vendor.ptb_urllib3.urllib3.connectionpool - WARNING - Retrying (Retry(total=1, connect=None, read=None, redirect=None)) after connection broken by 'NewConnectionError('<telegram.vendor.ptb_urllib3.urllib3.connection.VerifiedHTTPSConnection object at 0x116a50908>: Failed to establish a new connection: [Errno 8] nodename nor servname provided, or not known',)': /bot395861588:AAHXrGm2bD0VUDnVZLd6P45SzUas0e_SKNI/getUpdates\n",
      "2017-06-14 21:52:52,181 - telegram.vendor.ptb_urllib3.urllib3.connectionpool - WARNING - Retrying (Retry(total=0, connect=None, read=None, redirect=None)) after connection broken by 'NewConnectionError('<telegram.vendor.ptb_urllib3.urllib3.connection.VerifiedHTTPSConnection object at 0x116a50898>: Failed to establish a new connection: [Errno 8] nodename nor servname provided, or not known',)': /bot395861588:AAHXrGm2bD0VUDnVZLd6P45SzUas0e_SKNI/getUpdates\n",
      "2017-06-14 21:52:52,183 - telegram.ext.updater - ERROR - Error while getting Updates: urllib3 HTTPError HTTPSConnectionPool(host='api.telegram.org', port=443): Max retries exceeded with url: /bot395861588:AAHXrGm2bD0VUDnVZLd6P45SzUas0e_SKNI/getUpdates (Caused by NewConnectionError('<telegram.vendor.ptb_urllib3.urllib3.connection.VerifiedHTTPSConnection object at 0x116a50b70>: Failed to establish a new connection: [Errno 8] nodename nor servname provided, or not known',))\n",
      "2017-06-14 21:52:52,184 - __main__ - WARNING - Update \"None\" caused error \"urllib3 HTTPError HTTPSConnectionPool(host='api.telegram.org', port=443): Max retries exceeded with url: /bot395861588:AAHXrGm2bD0VUDnVZLd6P45SzUas0e_SKNI/getUpdates (Caused by NewConnectionError('<telegram.vendor.ptb_urllib3.urllib3.connection.VerifiedHTTPSConnection object at 0x116a50b70>: Failed to establish a new connection: [Errno 8] nodename nor servname provided, or not known',))\"\n",
      "2017-06-14 21:52:55,561 - telegram.vendor.ptb_urllib3.urllib3.connectionpool - WARNING - Retrying (Retry(total=2, connect=None, read=None, redirect=None)) after connection broken by 'NewConnectionError('<telegram.vendor.ptb_urllib3.urllib3.connection.VerifiedHTTPSConnection object at 0x116a502e8>: Failed to establish a new connection: [Errno 8] nodename nor servname provided, or not known',)': /bot395861588:AAHXrGm2bD0VUDnVZLd6P45SzUas0e_SKNI/getUpdates\n",
      "2017-06-14 21:52:55,563 - telegram.vendor.ptb_urllib3.urllib3.connectionpool - WARNING - Retrying (Retry(total=1, connect=None, read=None, redirect=None)) after connection broken by 'NewConnectionError('<telegram.vendor.ptb_urllib3.urllib3.connection.VerifiedHTTPSConnection object at 0x116a50d68>: Failed to establish a new connection: [Errno 8] nodename nor servname provided, or not known',)': /bot395861588:AAHXrGm2bD0VUDnVZLd6P45SzUas0e_SKNI/getUpdates\n",
      "2017-06-14 21:52:55,564 - telegram.vendor.ptb_urllib3.urllib3.connectionpool - WARNING - Retrying (Retry(total=0, connect=None, read=None, redirect=None)) after connection broken by 'NewConnectionError('<telegram.vendor.ptb_urllib3.urllib3.connection.VerifiedHTTPSConnection object at 0x116a50be0>: Failed to establish a new connection: [Errno 8] nodename nor servname provided, or not known',)': /bot395861588:AAHXrGm2bD0VUDnVZLd6P45SzUas0e_SKNI/getUpdates\n",
      "2017-06-14 21:52:55,574 - telegram.ext.updater - ERROR - Error while getting Updates: urllib3 HTTPError HTTPSConnectionPool(host='api.telegram.org', port=443): Max retries exceeded with url: /bot395861588:AAHXrGm2bD0VUDnVZLd6P45SzUas0e_SKNI/getUpdates (Caused by NewConnectionError('<telegram.vendor.ptb_urllib3.urllib3.connection.VerifiedHTTPSConnection object at 0x116a50da0>: Failed to establish a new connection: [Errno 8] nodename nor servname provided, or not known',))\n",
      "2017-06-14 21:52:55,575 - __main__ - WARNING - Update \"None\" caused error \"urllib3 HTTPError HTTPSConnectionPool(host='api.telegram.org', port=443): Max retries exceeded with url: /bot395861588:AAHXrGm2bD0VUDnVZLd6P45SzUas0e_SKNI/getUpdates (Caused by NewConnectionError('<telegram.vendor.ptb_urllib3.urllib3.connection.VerifiedHTTPSConnection object at 0x116a50da0>: Failed to establish a new connection: [Errno 8] nodename nor servname provided, or not known',))\"\n",
      "2017-06-14 21:53:00,657 - telegram.vendor.ptb_urllib3.urllib3.connectionpool - WARNING - Retrying (Retry(total=2, connect=None, read=None, redirect=None)) after connection broken by 'NewConnectionError('<telegram.vendor.ptb_urllib3.urllib3.connection.VerifiedHTTPSConnection object at 0x116a50cc0>: Failed to establish a new connection: [Errno 8] nodename nor servname provided, or not known',)': /bot395861588:AAHXrGm2bD0VUDnVZLd6P45SzUas0e_SKNI/getUpdates\n",
      "2017-06-14 21:53:00,681 - telegram.vendor.ptb_urllib3.urllib3.connectionpool - WARNING - Retrying (Retry(total=1, connect=None, read=None, redirect=None)) after connection broken by 'NewConnectionError('<telegram.vendor.ptb_urllib3.urllib3.connection.VerifiedHTTPSConnection object at 0x116a35550>: Failed to establish a new connection: [Errno 8] nodename nor servname provided, or not known',)': /bot395861588:AAHXrGm2bD0VUDnVZLd6P45SzUas0e_SKNI/getUpdates\n",
      "2017-06-14 21:53:00,687 - telegram.vendor.ptb_urllib3.urllib3.connectionpool - WARNING - Retrying (Retry(total=0, connect=None, read=None, redirect=None)) after connection broken by 'NewConnectionError('<telegram.vendor.ptb_urllib3.urllib3.connection.VerifiedHTTPSConnection object at 0x116a35208>: Failed to establish a new connection: [Errno 8] nodename nor servname provided, or not known',)': /bot395861588:AAHXrGm2bD0VUDnVZLd6P45SzUas0e_SKNI/getUpdates\n",
      "2017-06-14 21:53:00,698 - telegram.ext.updater - ERROR - Error while getting Updates: urllib3 HTTPError HTTPSConnectionPool(host='api.telegram.org', port=443): Max retries exceeded with url: /bot395861588:AAHXrGm2bD0VUDnVZLd6P45SzUas0e_SKNI/getUpdates (Caused by NewConnectionError('<telegram.vendor.ptb_urllib3.urllib3.connection.VerifiedHTTPSConnection object at 0x1169a3c50>: Failed to establish a new connection: [Errno 8] nodename nor servname provided, or not known',))\n",
      "2017-06-14 21:53:00,728 - __main__ - WARNING - Update \"None\" caused error \"urllib3 HTTPError HTTPSConnectionPool(host='api.telegram.org', port=443): Max retries exceeded with url: /bot395861588:AAHXrGm2bD0VUDnVZLd6P45SzUas0e_SKNI/getUpdates (Caused by NewConnectionError('<telegram.vendor.ptb_urllib3.urllib3.connection.VerifiedHTTPSConnection object at 0x1169a3c50>: Failed to establish a new connection: [Errno 8] nodename nor servname provided, or not known',))\"\n",
      "2017-06-14 22:47:10,663 - telegram.ext.updater - ERROR - Error while getting Updates: Timed out\n",
      "2017-06-14 22:47:10,668 - __main__ - WARNING - Update \"None\" caused error \"Timed out\"\n",
      "2017-06-14 22:47:18,258 - telegram.vendor.ptb_urllib3.urllib3.connectionpool - WARNING - Retrying (Retry(total=2, connect=None, read=None, redirect=None)) after connection broken by 'NewConnectionError('<telegram.vendor.ptb_urllib3.urllib3.connection.VerifiedHTTPSConnection object at 0x116a508d0>: Failed to establish a new connection: [Errno 8] nodename nor servname provided, or not known',)': /bot395861588:AAHXrGm2bD0VUDnVZLd6P45SzUas0e_SKNI/getUpdates\n",
      "2017-06-14 22:47:18,263 - telegram.vendor.ptb_urllib3.urllib3.connectionpool - WARNING - Retrying (Retry(total=1, connect=None, read=None, redirect=None)) after connection broken by 'NewConnectionError('<telegram.vendor.ptb_urllib3.urllib3.connection.VerifiedHTTPSConnection object at 0x1169a3fd0>: Failed to establish a new connection: [Errno 8] nodename nor servname provided, or not known',)': /bot395861588:AAHXrGm2bD0VUDnVZLd6P45SzUas0e_SKNI/getUpdates\n",
      "2017-06-14 22:47:18,358 - telegram.vendor.ptb_urllib3.urllib3.connectionpool - WARNING - Retrying (Retry(total=0, connect=None, read=None, redirect=None)) after connection broken by 'NewConnectionError('<telegram.vendor.ptb_urllib3.urllib3.connection.VerifiedHTTPSConnection object at 0x1169a3748>: Failed to establish a new connection: [Errno 8] nodename nor servname provided, or not known',)': /bot395861588:AAHXrGm2bD0VUDnVZLd6P45SzUas0e_SKNI/getUpdates\n",
      "2017-06-14 22:47:18,378 - telegram.ext.updater - ERROR - Error while getting Updates: urllib3 HTTPError HTTPSConnectionPool(host='api.telegram.org', port=443): Max retries exceeded with url: /bot395861588:AAHXrGm2bD0VUDnVZLd6P45SzUas0e_SKNI/getUpdates (Caused by NewConnectionError('<telegram.vendor.ptb_urllib3.urllib3.connection.VerifiedHTTPSConnection object at 0x1169a3860>: Failed to establish a new connection: [Errno 8] nodename nor servname provided, or not known',))\n",
      "2017-06-14 22:47:18,379 - __main__ - WARNING - Update \"None\" caused error \"urllib3 HTTPError HTTPSConnectionPool(host='api.telegram.org', port=443): Max retries exceeded with url: /bot395861588:AAHXrGm2bD0VUDnVZLd6P45SzUas0e_SKNI/getUpdates (Caused by NewConnectionError('<telegram.vendor.ptb_urllib3.urllib3.connection.VerifiedHTTPSConnection object at 0x1169a3860>: Failed to establish a new connection: [Errno 8] nodename nor servname provided, or not known',))\"\n",
      "2017-06-14 22:47:19,885 - telegram.vendor.ptb_urllib3.urllib3.connectionpool - WARNING - Retrying (Retry(total=2, connect=None, read=None, redirect=None)) after connection broken by 'NewConnectionError('<telegram.vendor.ptb_urllib3.urllib3.connection.VerifiedHTTPSConnection object at 0x116a1c710>: Failed to establish a new connection: [Errno 8] nodename nor servname provided, or not known',)': /bot395861588:AAHXrGm2bD0VUDnVZLd6P45SzUas0e_SKNI/getUpdates\n",
      "2017-06-14 22:47:19,887 - telegram.vendor.ptb_urllib3.urllib3.connectionpool - WARNING - Retrying (Retry(total=1, connect=None, read=None, redirect=None)) after connection broken by 'NewConnectionError('<telegram.vendor.ptb_urllib3.urllib3.connection.VerifiedHTTPSConnection object at 0x116a1c9b0>: Failed to establish a new connection: [Errno 8] nodename nor servname provided, or not known',)': /bot395861588:AAHXrGm2bD0VUDnVZLd6P45SzUas0e_SKNI/getUpdates\n",
      "2017-06-14 22:47:19,888 - telegram.vendor.ptb_urllib3.urllib3.connectionpool - WARNING - Retrying (Retry(total=0, connect=None, read=None, redirect=None)) after connection broken by 'NewConnectionError('<telegram.vendor.ptb_urllib3.urllib3.connection.VerifiedHTTPSConnection object at 0x116a1c5c0>: Failed to establish a new connection: [Errno 8] nodename nor servname provided, or not known',)': /bot395861588:AAHXrGm2bD0VUDnVZLd6P45SzUas0e_SKNI/getUpdates\n",
      "2017-06-14 22:47:19,890 - telegram.ext.updater - ERROR - Error while getting Updates: urllib3 HTTPError HTTPSConnectionPool(host='api.telegram.org', port=443): Max retries exceeded with url: /bot395861588:AAHXrGm2bD0VUDnVZLd6P45SzUas0e_SKNI/getUpdates (Caused by NewConnectionError('<telegram.vendor.ptb_urllib3.urllib3.connection.VerifiedHTTPSConnection object at 0x116a1cda0>: Failed to establish a new connection: [Errno 8] nodename nor servname provided, or not known',))\n",
      "2017-06-14 22:47:19,891 - __main__ - WARNING - Update \"None\" caused error \"urllib3 HTTPError HTTPSConnectionPool(host='api.telegram.org', port=443): Max retries exceeded with url: /bot395861588:AAHXrGm2bD0VUDnVZLd6P45SzUas0e_SKNI/getUpdates (Caused by NewConnectionError('<telegram.vendor.ptb_urllib3.urllib3.connection.VerifiedHTTPSConnection object at 0x116a1cda0>: Failed to establish a new connection: [Errno 8] nodename nor servname provided, or not known',))\"\n",
      "2017-06-14 22:47:22,143 - telegram.vendor.ptb_urllib3.urllib3.connectionpool - WARNING - Retrying (Retry(total=2, connect=None, read=None, redirect=None)) after connection broken by 'NewConnectionError('<telegram.vendor.ptb_urllib3.urllib3.connection.VerifiedHTTPSConnection object at 0x116754da0>: Failed to establish a new connection: [Errno 8] nodename nor servname provided, or not known',)': /bot395861588:AAHXrGm2bD0VUDnVZLd6P45SzUas0e_SKNI/getUpdates\n",
      "2017-06-14 22:47:22,144 - telegram.vendor.ptb_urllib3.urllib3.connectionpool - WARNING - Retrying (Retry(total=1, connect=None, read=None, redirect=None)) after connection broken by 'NewConnectionError('<telegram.vendor.ptb_urllib3.urllib3.connection.VerifiedHTTPSConnection object at 0x116995eb8>: Failed to establish a new connection: [Errno 8] nodename nor servname provided, or not known',)': /bot395861588:AAHXrGm2bD0VUDnVZLd6P45SzUas0e_SKNI/getUpdates\n",
      "2017-06-14 22:47:22,146 - telegram.vendor.ptb_urllib3.urllib3.connectionpool - WARNING - Retrying (Retry(total=0, connect=None, read=None, redirect=None)) after connection broken by 'NewConnectionError('<telegram.vendor.ptb_urllib3.urllib3.connection.VerifiedHTTPSConnection object at 0x116a1cc88>: Failed to establish a new connection: [Errno 8] nodename nor servname provided, or not known',)': /bot395861588:AAHXrGm2bD0VUDnVZLd6P45SzUas0e_SKNI/getUpdates\n",
      "2017-06-14 22:47:22,147 - telegram.ext.updater - ERROR - Error while getting Updates: urllib3 HTTPError HTTPSConnectionPool(host='api.telegram.org', port=443): Max retries exceeded with url: /bot395861588:AAHXrGm2bD0VUDnVZLd6P45SzUas0e_SKNI/getUpdates (Caused by NewConnectionError('<telegram.vendor.ptb_urllib3.urllib3.connection.VerifiedHTTPSConnection object at 0x116a1ce48>: Failed to establish a new connection: [Errno 8] nodename nor servname provided, or not known',))\n",
      "2017-06-14 22:47:22,148 - __main__ - WARNING - Update \"None\" caused error \"urllib3 HTTPError HTTPSConnectionPool(host='api.telegram.org', port=443): Max retries exceeded with url: /bot395861588:AAHXrGm2bD0VUDnVZLd6P45SzUas0e_SKNI/getUpdates (Caused by NewConnectionError('<telegram.vendor.ptb_urllib3.urllib3.connection.VerifiedHTTPSConnection object at 0x116a1ce48>: Failed to establish a new connection: [Errno 8] nodename nor servname provided, or not known',))\"\n",
      "2017-06-14 22:47:25,524 - telegram.vendor.ptb_urllib3.urllib3.connectionpool - WARNING - Retrying (Retry(total=2, connect=None, read=None, redirect=None)) after connection broken by 'NewConnectionError('<telegram.vendor.ptb_urllib3.urllib3.connection.VerifiedHTTPSConnection object at 0x116754e80>: Failed to establish a new connection: [Errno 8] nodename nor servname provided, or not known',)': /bot395861588:AAHXrGm2bD0VUDnVZLd6P45SzUas0e_SKNI/getUpdates\n",
      "2017-06-14 22:47:25,528 - telegram.vendor.ptb_urllib3.urllib3.connectionpool - WARNING - Retrying (Retry(total=1, connect=None, read=None, redirect=None)) after connection broken by 'NewConnectionError('<telegram.vendor.ptb_urllib3.urllib3.connection.VerifiedHTTPSConnection object at 0x116a5e278>: Failed to establish a new connection: [Errno 8] nodename nor servname provided, or not known',)': /bot395861588:AAHXrGm2bD0VUDnVZLd6P45SzUas0e_SKNI/getUpdates\n",
      "2017-06-14 22:47:25,531 - telegram.vendor.ptb_urllib3.urllib3.connectionpool - WARNING - Retrying (Retry(total=0, connect=None, read=None, redirect=None)) after connection broken by 'NewConnectionError('<telegram.vendor.ptb_urllib3.urllib3.connection.VerifiedHTTPSConnection object at 0x116a5e240>: Failed to establish a new connection: [Errno 8] nodename nor servname provided, or not known',)': /bot395861588:AAHXrGm2bD0VUDnVZLd6P45SzUas0e_SKNI/getUpdates\n",
      "2017-06-14 22:47:25,534 - telegram.ext.updater - ERROR - Error while getting Updates: urllib3 HTTPError HTTPSConnectionPool(host='api.telegram.org', port=443): Max retries exceeded with url: /bot395861588:AAHXrGm2bD0VUDnVZLd6P45SzUas0e_SKNI/getUpdates (Caused by NewConnectionError('<telegram.vendor.ptb_urllib3.urllib3.connection.VerifiedHTTPSConnection object at 0x116a5e470>: Failed to establish a new connection: [Errno 8] nodename nor servname provided, or not known',))\n",
      "2017-06-14 22:47:25,535 - __main__ - WARNING - Update \"None\" caused error \"urllib3 HTTPError HTTPSConnectionPool(host='api.telegram.org', port=443): Max retries exceeded with url: /bot395861588:AAHXrGm2bD0VUDnVZLd6P45SzUas0e_SKNI/getUpdates (Caused by NewConnectionError('<telegram.vendor.ptb_urllib3.urllib3.connection.VerifiedHTTPSConnection object at 0x116a5e470>: Failed to establish a new connection: [Errno 8] nodename nor servname provided, or not known',))\"\n",
      "2017-06-14 22:47:30,599 - telegram.vendor.ptb_urllib3.urllib3.connectionpool - WARNING - Retrying (Retry(total=2, connect=None, read=None, redirect=None)) after connection broken by 'NewConnectionError('<telegram.vendor.ptb_urllib3.urllib3.connection.VerifiedHTTPSConnection object at 0x116a5e208>: Failed to establish a new connection: [Errno 8] nodename nor servname provided, or not known',)': /bot395861588:AAHXrGm2bD0VUDnVZLd6P45SzUas0e_SKNI/getUpdates\n",
      "2017-06-14 22:47:30,600 - telegram.vendor.ptb_urllib3.urllib3.connectionpool - WARNING - Retrying (Retry(total=1, connect=None, read=None, redirect=None)) after connection broken by 'NewConnectionError('<telegram.vendor.ptb_urllib3.urllib3.connection.VerifiedHTTPSConnection object at 0x116a5e4e0>: Failed to establish a new connection: [Errno 8] nodename nor servname provided, or not known',)': /bot395861588:AAHXrGm2bD0VUDnVZLd6P45SzUas0e_SKNI/getUpdates\n",
      "2017-06-14 22:47:30,601 - telegram.vendor.ptb_urllib3.urllib3.connectionpool - WARNING - Retrying (Retry(total=0, connect=None, read=None, redirect=None)) after connection broken by 'NewConnectionError('<telegram.vendor.ptb_urllib3.urllib3.connection.VerifiedHTTPSConnection object at 0x116a5e668>: Failed to establish a new connection: [Errno 8] nodename nor servname provided, or not known',)': /bot395861588:AAHXrGm2bD0VUDnVZLd6P45SzUas0e_SKNI/getUpdates\n",
      "2017-06-14 23:41:37,965 - telegram.ext.updater - ERROR - Error while getting Updates: Timed out\n",
      "2017-06-14 23:41:37,971 - __main__ - WARNING - Update \"None\" caused error \"Timed out\"\n",
      "2017-06-14 23:41:46,952 - telegram.vendor.ptb_urllib3.urllib3.connectionpool - WARNING - Retrying (Retry(total=2, connect=None, read=None, redirect=None)) after connection broken by 'NewConnectionError('<telegram.vendor.ptb_urllib3.urllib3.connection.VerifiedHTTPSConnection object at 0x116a50b70>: Failed to establish a new connection: [Errno 8] nodename nor servname provided, or not known',)': /bot395861588:AAHXrGm2bD0VUDnVZLd6P45SzUas0e_SKNI/getUpdates\n",
      "2017-06-14 23:41:46,975 - telegram.vendor.ptb_urllib3.urllib3.connectionpool - WARNING - Retrying (Retry(total=1, connect=None, read=None, redirect=None)) after connection broken by 'NewConnectionError('<telegram.vendor.ptb_urllib3.urllib3.connection.VerifiedHTTPSConnection object at 0x116a50a90>: Failed to establish a new connection: [Errno 8] nodename nor servname provided, or not known',)': /bot395861588:AAHXrGm2bD0VUDnVZLd6P45SzUas0e_SKNI/getUpdates\n",
      "2017-06-14 23:41:46,999 - telegram.vendor.ptb_urllib3.urllib3.connectionpool - WARNING - Retrying (Retry(total=0, connect=None, read=None, redirect=None)) after connection broken by 'NewConnectionError('<telegram.vendor.ptb_urllib3.urllib3.connection.VerifiedHTTPSConnection object at 0x116a50908>: Failed to establish a new connection: [Errno 8] nodename nor servname provided, or not known',)': /bot395861588:AAHXrGm2bD0VUDnVZLd6P45SzUas0e_SKNI/getUpdates\n",
      "2017-06-14 23:41:47,002 - telegram.ext.updater - ERROR - Error while getting Updates: urllib3 HTTPError HTTPSConnectionPool(host='api.telegram.org', port=443): Max retries exceeded with url: /bot395861588:AAHXrGm2bD0VUDnVZLd6P45SzUas0e_SKNI/getUpdates (Caused by NewConnectionError('<telegram.vendor.ptb_urllib3.urllib3.connection.VerifiedHTTPSConnection object at 0x116a50ef0>: Failed to establish a new connection: [Errno 8] nodename nor servname provided, or not known',))\n",
      "2017-06-14 23:41:47,003 - __main__ - WARNING - Update \"None\" caused error \"urllib3 HTTPError HTTPSConnectionPool(host='api.telegram.org', port=443): Max retries exceeded with url: /bot395861588:AAHXrGm2bD0VUDnVZLd6P45SzUas0e_SKNI/getUpdates (Caused by NewConnectionError('<telegram.vendor.ptb_urllib3.urllib3.connection.VerifiedHTTPSConnection object at 0x116a50ef0>: Failed to establish a new connection: [Errno 8] nodename nor servname provided, or not known',))\"\n",
      "2017-06-14 23:41:48,516 - telegram.vendor.ptb_urllib3.urllib3.connectionpool - WARNING - Retrying (Retry(total=2, connect=None, read=None, redirect=None)) after connection broken by 'NewConnectionError('<telegram.vendor.ptb_urllib3.urllib3.connection.VerifiedHTTPSConnection object at 0x116a50fd0>: Failed to establish a new connection: [Errno 8] nodename nor servname provided, or not known',)': /bot395861588:AAHXrGm2bD0VUDnVZLd6P45SzUas0e_SKNI/getUpdates\n",
      "2017-06-14 23:41:48,519 - telegram.vendor.ptb_urllib3.urllib3.connectionpool - WARNING - Retrying (Retry(total=1, connect=None, read=None, redirect=None)) after connection broken by 'NewConnectionError('<telegram.vendor.ptb_urllib3.urllib3.connection.VerifiedHTTPSConnection object at 0x116a504a8>: Failed to establish a new connection: [Errno 8] nodename nor servname provided, or not known',)': /bot395861588:AAHXrGm2bD0VUDnVZLd6P45SzUas0e_SKNI/getUpdates\n",
      "2017-06-14 23:41:48,521 - telegram.vendor.ptb_urllib3.urllib3.connectionpool - WARNING - Retrying (Retry(total=0, connect=None, read=None, redirect=None)) after connection broken by 'NewConnectionError('<telegram.vendor.ptb_urllib3.urllib3.connection.VerifiedHTTPSConnection object at 0x116a50f98>: Failed to establish a new connection: [Errno 8] nodename nor servname provided, or not known',)': /bot395861588:AAHXrGm2bD0VUDnVZLd6P45SzUas0e_SKNI/getUpdates\n",
      "2017-06-14 23:41:48,524 - telegram.ext.updater - ERROR - Error while getting Updates: urllib3 HTTPError HTTPSConnectionPool(host='api.telegram.org', port=443): Max retries exceeded with url: /bot395861588:AAHXrGm2bD0VUDnVZLd6P45SzUas0e_SKNI/getUpdates (Caused by NewConnectionError('<telegram.vendor.ptb_urllib3.urllib3.connection.VerifiedHTTPSConnection object at 0x116a50160>: Failed to establish a new connection: [Errno 8] nodename nor servname provided, or not known',))\n",
      "2017-06-14 23:41:48,526 - __main__ - WARNING - Update \"None\" caused error \"urllib3 HTTPError HTTPSConnectionPool(host='api.telegram.org', port=443): Max retries exceeded with url: /bot395861588:AAHXrGm2bD0VUDnVZLd6P45SzUas0e_SKNI/getUpdates (Caused by NewConnectionError('<telegram.vendor.ptb_urllib3.urllib3.connection.VerifiedHTTPSConnection object at 0x116a50160>: Failed to establish a new connection: [Errno 8] nodename nor servname provided, or not known',))\"\n",
      "2017-06-14 23:41:50,784 - telegram.vendor.ptb_urllib3.urllib3.connectionpool - WARNING - Retrying (Retry(total=2, connect=None, read=None, redirect=None)) after connection broken by 'NewConnectionError('<telegram.vendor.ptb_urllib3.urllib3.connection.VerifiedHTTPSConnection object at 0x116a501d0>: Failed to establish a new connection: [Errno 8] nodename nor servname provided, or not known',)': /bot395861588:AAHXrGm2bD0VUDnVZLd6P45SzUas0e_SKNI/getUpdates\n",
      "2017-06-14 23:41:50,786 - telegram.vendor.ptb_urllib3.urllib3.connectionpool - WARNING - Retrying (Retry(total=1, connect=None, read=None, redirect=None)) after connection broken by 'NewConnectionError('<telegram.vendor.ptb_urllib3.urllib3.connection.VerifiedHTTPSConnection object at 0x116a50438>: Failed to establish a new connection: [Errno 8] nodename nor servname provided, or not known',)': /bot395861588:AAHXrGm2bD0VUDnVZLd6P45SzUas0e_SKNI/getUpdates\n",
      "2017-06-14 23:41:50,787 - telegram.vendor.ptb_urllib3.urllib3.connectionpool - WARNING - Retrying (Retry(total=0, connect=None, read=None, redirect=None)) after connection broken by 'NewConnectionError('<telegram.vendor.ptb_urllib3.urllib3.connection.VerifiedHTTPSConnection object at 0x116a502e8>: Failed to establish a new connection: [Errno 8] nodename nor servname provided, or not known',)': /bot395861588:AAHXrGm2bD0VUDnVZLd6P45SzUas0e_SKNI/getUpdates\n",
      "2017-06-14 23:41:50,789 - telegram.ext.updater - ERROR - Error while getting Updates: urllib3 HTTPError HTTPSConnectionPool(host='api.telegram.org', port=443): Max retries exceeded with url: /bot395861588:AAHXrGm2bD0VUDnVZLd6P45SzUas0e_SKNI/getUpdates (Caused by NewConnectionError('<telegram.vendor.ptb_urllib3.urllib3.connection.VerifiedHTTPSConnection object at 0x116a505c0>: Failed to establish a new connection: [Errno 8] nodename nor servname provided, or not known',))\n",
      "2017-06-14 23:41:50,790 - __main__ - WARNING - Update \"None\" caused error \"urllib3 HTTPError HTTPSConnectionPool(host='api.telegram.org', port=443): Max retries exceeded with url: /bot395861588:AAHXrGm2bD0VUDnVZLd6P45SzUas0e_SKNI/getUpdates (Caused by NewConnectionError('<telegram.vendor.ptb_urllib3.urllib3.connection.VerifiedHTTPSConnection object at 0x116a505c0>: Failed to establish a new connection: [Errno 8] nodename nor servname provided, or not known',))\"\n",
      "2017-06-14 23:41:54,241 - telegram.vendor.ptb_urllib3.urllib3.connectionpool - WARNING - Retrying (Retry(total=2, connect=None, read=None, redirect=None)) after connection broken by 'NewConnectionError('<telegram.vendor.ptb_urllib3.urllib3.connection.VerifiedHTTPSConnection object at 0x116a50f28>: Failed to establish a new connection: [Errno 8] nodename nor servname provided, or not known',)': /bot395861588:AAHXrGm2bD0VUDnVZLd6P45SzUas0e_SKNI/getUpdates\n",
      "2017-06-14 23:41:54,246 - telegram.vendor.ptb_urllib3.urllib3.connectionpool - WARNING - Retrying (Retry(total=1, connect=None, read=None, redirect=None)) after connection broken by 'NewConnectionError('<telegram.vendor.ptb_urllib3.urllib3.connection.VerifiedHTTPSConnection object at 0x116a356d8>: Failed to establish a new connection: [Errno 8] nodename nor servname provided, or not known',)': /bot395861588:AAHXrGm2bD0VUDnVZLd6P45SzUas0e_SKNI/getUpdates\n",
      "2017-06-14 23:41:54,248 - telegram.vendor.ptb_urllib3.urllib3.connectionpool - WARNING - Retrying (Retry(total=0, connect=None, read=None, redirect=None)) after connection broken by 'NewConnectionError('<telegram.vendor.ptb_urllib3.urllib3.connection.VerifiedHTTPSConnection object at 0x116a35668>: Failed to establish a new connection: [Errno 8] nodename nor servname provided, or not known',)': /bot395861588:AAHXrGm2bD0VUDnVZLd6P45SzUas0e_SKNI/getUpdates\n",
      "2017-06-14 23:41:54,252 - telegram.ext.updater - ERROR - Error while getting Updates: urllib3 HTTPError HTTPSConnectionPool(host='api.telegram.org', port=443): Max retries exceeded with url: /bot395861588:AAHXrGm2bD0VUDnVZLd6P45SzUas0e_SKNI/getUpdates (Caused by NewConnectionError('<telegram.vendor.ptb_urllib3.urllib3.connection.VerifiedHTTPSConnection object at 0x116a35a58>: Failed to establish a new connection: [Errno 8] nodename nor servname provided, or not known',))\n",
      "2017-06-14 23:41:54,254 - __main__ - WARNING - Update \"None\" caused error \"urllib3 HTTPError HTTPSConnectionPool(host='api.telegram.org', port=443): Max retries exceeded with url: /bot395861588:AAHXrGm2bD0VUDnVZLd6P45SzUas0e_SKNI/getUpdates (Caused by NewConnectionError('<telegram.vendor.ptb_urllib3.urllib3.connection.VerifiedHTTPSConnection object at 0x116a35a58>: Failed to establish a new connection: [Errno 8] nodename nor servname provided, or not known',))\"\n",
      "2017-06-14 23:41:59,318 - telegram.vendor.ptb_urllib3.urllib3.connectionpool - WARNING - Retrying (Retry(total=2, connect=None, read=None, redirect=None)) after connection broken by 'NewConnectionError('<telegram.vendor.ptb_urllib3.urllib3.connection.VerifiedHTTPSConnection object at 0x116a35b38>: Failed to establish a new connection: [Errno 8] nodename nor servname provided, or not known',)': /bot395861588:AAHXrGm2bD0VUDnVZLd6P45SzUas0e_SKNI/getUpdates\n",
      "2017-06-14 23:41:59,320 - telegram.vendor.ptb_urllib3.urllib3.connectionpool - WARNING - Retrying (Retry(total=1, connect=None, read=None, redirect=None)) after connection broken by 'NewConnectionError('<telegram.vendor.ptb_urllib3.urllib3.connection.VerifiedHTTPSConnection object at 0x116a35518>: Failed to establish a new connection: [Errno 8] nodename nor servname provided, or not known',)': /bot395861588:AAHXrGm2bD0VUDnVZLd6P45SzUas0e_SKNI/getUpdates\n",
      "2017-06-14 23:41:59,321 - telegram.vendor.ptb_urllib3.urllib3.connectionpool - WARNING - Retrying (Retry(total=0, connect=None, read=None, redirect=None)) after connection broken by 'NewConnectionError('<telegram.vendor.ptb_urllib3.urllib3.connection.VerifiedHTTPSConnection object at 0x116a35e80>: Failed to establish a new connection: [Errno 8] nodename nor servname provided, or not known',)': /bot395861588:AAHXrGm2bD0VUDnVZLd6P45SzUas0e_SKNI/getUpdates\n",
      "2017-06-14 23:41:59,322 - telegram.ext.updater - ERROR - Error while getting Updates: urllib3 HTTPError HTTPSConnectionPool(host='api.telegram.org', port=443): Max retries exceeded with url: /bot395861588:AAHXrGm2bD0VUDnVZLd6P45SzUas0e_SKNI/getUpdates (Caused by NewConnectionError('<telegram.vendor.ptb_urllib3.urllib3.connection.VerifiedHTTPSConnection object at 0x116a35eb8>: Failed to establish a new connection: [Errno 8] nodename nor servname provided, or not known',))\n",
      "2017-06-14 23:41:59,323 - __main__ - WARNING - Update \"None\" caused error \"urllib3 HTTPError HTTPSConnectionPool(host='api.telegram.org', port=443): Max retries exceeded with url: /bot395861588:AAHXrGm2bD0VUDnVZLd6P45SzUas0e_SKNI/getUpdates (Caused by NewConnectionError('<telegram.vendor.ptb_urllib3.urllib3.connection.VerifiedHTTPSConnection object at 0x116a35eb8>: Failed to establish a new connection: [Errno 8] nodename nor servname provided, or not known',))\"\n",
      "2017-06-15 00:36:10,389 - telegram.ext.updater - ERROR - Error while getting Updates: Timed out\n",
      "2017-06-15 00:36:10,394 - __main__ - WARNING - Update \"None\" caused error \"Timed out\"\n",
      "2017-06-15 00:36:18,050 - telegram.vendor.ptb_urllib3.urllib3.connectionpool - WARNING - Retrying (Retry(total=2, connect=None, read=None, redirect=None)) after connection broken by 'NewConnectionError('<telegram.vendor.ptb_urllib3.urllib3.connection.VerifiedHTTPSConnection object at 0x116a35748>: Failed to establish a new connection: [Errno 8] nodename nor servname provided, or not known',)': /bot395861588:AAHXrGm2bD0VUDnVZLd6P45SzUas0e_SKNI/getUpdates\n",
      "2017-06-15 00:36:18,363 - telegram.vendor.ptb_urllib3.urllib3.connectionpool - WARNING - Retrying (Retry(total=1, connect=None, read=None, redirect=None)) after connection broken by 'NewConnectionError('<telegram.vendor.ptb_urllib3.urllib3.connection.VerifiedHTTPSConnection object at 0x116a35160>: Failed to establish a new connection: [Errno 8] nodename nor servname provided, or not known',)': /bot395861588:AAHXrGm2bD0VUDnVZLd6P45SzUas0e_SKNI/getUpdates\n",
      "2017-06-15 00:36:18,940 - telegram.vendor.ptb_urllib3.urllib3.connectionpool - WARNING - Retrying (Retry(total=0, connect=None, read=None, redirect=None)) after connection broken by 'NewConnectionError('<telegram.vendor.ptb_urllib3.urllib3.connection.VerifiedHTTPSConnection object at 0x116a35630>: Failed to establish a new connection: [Errno 8] nodename nor servname provided, or not known',)': /bot395861588:AAHXrGm2bD0VUDnVZLd6P45SzUas0e_SKNI/getUpdates\n",
      "2017-06-15 00:36:18,941 - telegram.ext.updater - ERROR - Error while getting Updates: urllib3 HTTPError HTTPSConnectionPool(host='api.telegram.org', port=443): Max retries exceeded with url: /bot395861588:AAHXrGm2bD0VUDnVZLd6P45SzUas0e_SKNI/getUpdates (Caused by NewConnectionError('<telegram.vendor.ptb_urllib3.urllib3.connection.VerifiedHTTPSConnection object at 0x116a35320>: Failed to establish a new connection: [Errno 8] nodename nor servname provided, or not known',))\n",
      "2017-06-15 00:36:18,942 - __main__ - WARNING - Update \"None\" caused error \"urllib3 HTTPError HTTPSConnectionPool(host='api.telegram.org', port=443): Max retries exceeded with url: /bot395861588:AAHXrGm2bD0VUDnVZLd6P45SzUas0e_SKNI/getUpdates (Caused by NewConnectionError('<telegram.vendor.ptb_urllib3.urllib3.connection.VerifiedHTTPSConnection object at 0x116a35320>: Failed to establish a new connection: [Errno 8] nodename nor servname provided, or not known',))\"\n",
      "2017-06-15 00:36:20,455 - telegram.vendor.ptb_urllib3.urllib3.connectionpool - WARNING - Retrying (Retry(total=2, connect=None, read=None, redirect=None)) after connection broken by 'NewConnectionError('<telegram.vendor.ptb_urllib3.urllib3.connection.VerifiedHTTPSConnection object at 0x116a35c50>: Failed to establish a new connection: [Errno 8] nodename nor servname provided, or not known',)': /bot395861588:AAHXrGm2bD0VUDnVZLd6P45SzUas0e_SKNI/getUpdates\n",
      "2017-06-15 00:36:20,457 - telegram.vendor.ptb_urllib3.urllib3.connectionpool - WARNING - Retrying (Retry(total=1, connect=None, read=None, redirect=None)) after connection broken by 'NewConnectionError('<telegram.vendor.ptb_urllib3.urllib3.connection.VerifiedHTTPSConnection object at 0x116a35400>: Failed to establish a new connection: [Errno 8] nodename nor servname provided, or not known',)': /bot395861588:AAHXrGm2bD0VUDnVZLd6P45SzUas0e_SKNI/getUpdates\n",
      "2017-06-15 00:36:20,652 - telegram.vendor.ptb_urllib3.urllib3.connectionpool - WARNING - Retrying (Retry(total=0, connect=None, read=None, redirect=None)) after connection broken by 'NewConnectionError('<telegram.vendor.ptb_urllib3.urllib3.connection.VerifiedHTTPSConnection object at 0x116a35710>: Failed to establish a new connection: [Errno 8] nodename nor servname provided, or not known',)': /bot395861588:AAHXrGm2bD0VUDnVZLd6P45SzUas0e_SKNI/getUpdates\n",
      "2017-06-15 00:36:20,653 - telegram.ext.updater - ERROR - Error while getting Updates: urllib3 HTTPError HTTPSConnectionPool(host='api.telegram.org', port=443): Max retries exceeded with url: /bot395861588:AAHXrGm2bD0VUDnVZLd6P45SzUas0e_SKNI/getUpdates (Caused by NewConnectionError('<telegram.vendor.ptb_urllib3.urllib3.connection.VerifiedHTTPSConnection object at 0x116a357f0>: Failed to establish a new connection: [Errno 8] nodename nor servname provided, or not known',))\n",
      "2017-06-15 00:36:20,654 - __main__ - WARNING - Update \"None\" caused error \"urllib3 HTTPError HTTPSConnectionPool(host='api.telegram.org', port=443): Max retries exceeded with url: /bot395861588:AAHXrGm2bD0VUDnVZLd6P45SzUas0e_SKNI/getUpdates (Caused by NewConnectionError('<telegram.vendor.ptb_urllib3.urllib3.connection.VerifiedHTTPSConnection object at 0x116a357f0>: Failed to establish a new connection: [Errno 8] nodename nor servname provided, or not known',))\"\n",
      "2017-06-15 00:36:22,906 - telegram.vendor.ptb_urllib3.urllib3.connectionpool - WARNING - Retrying (Retry(total=2, connect=None, read=None, redirect=None)) after connection broken by 'NewConnectionError('<telegram.vendor.ptb_urllib3.urllib3.connection.VerifiedHTTPSConnection object at 0x116a35d68>: Failed to establish a new connection: [Errno 8] nodename nor servname provided, or not known',)': /bot395861588:AAHXrGm2bD0VUDnVZLd6P45SzUas0e_SKNI/getUpdates\n",
      "2017-06-15 00:36:22,907 - telegram.vendor.ptb_urllib3.urllib3.connectionpool - WARNING - Retrying (Retry(total=1, connect=None, read=None, redirect=None)) after connection broken by 'NewConnectionError('<telegram.vendor.ptb_urllib3.urllib3.connection.VerifiedHTTPSConnection object at 0x116a35588>: Failed to establish a new connection: [Errno 8] nodename nor servname provided, or not known',)': /bot395861588:AAHXrGm2bD0VUDnVZLd6P45SzUas0e_SKNI/getUpdates\n",
      "2017-06-15 00:36:22,908 - telegram.vendor.ptb_urllib3.urllib3.connectionpool - WARNING - Retrying (Retry(total=0, connect=None, read=None, redirect=None)) after connection broken by 'NewConnectionError('<telegram.vendor.ptb_urllib3.urllib3.connection.VerifiedHTTPSConnection object at 0x116a35c88>: Failed to establish a new connection: [Errno 8] nodename nor servname provided, or not known',)': /bot395861588:AAHXrGm2bD0VUDnVZLd6P45SzUas0e_SKNI/getUpdates\n",
      "2017-06-15 00:36:22,909 - telegram.ext.updater - ERROR - Error while getting Updates: urllib3 HTTPError HTTPSConnectionPool(host='api.telegram.org', port=443): Max retries exceeded with url: /bot395861588:AAHXrGm2bD0VUDnVZLd6P45SzUas0e_SKNI/getUpdates (Caused by NewConnectionError('<telegram.vendor.ptb_urllib3.urllib3.connection.VerifiedHTTPSConnection object at 0x1100537b8>: Failed to establish a new connection: [Errno 8] nodename nor servname provided, or not known',))\n",
      "2017-06-15 00:36:22,910 - __main__ - WARNING - Update \"None\" caused error \"urllib3 HTTPError HTTPSConnectionPool(host='api.telegram.org', port=443): Max retries exceeded with url: /bot395861588:AAHXrGm2bD0VUDnVZLd6P45SzUas0e_SKNI/getUpdates (Caused by NewConnectionError('<telegram.vendor.ptb_urllib3.urllib3.connection.VerifiedHTTPSConnection object at 0x1100537b8>: Failed to establish a new connection: [Errno 8] nodename nor servname provided, or not known',))\"\n",
      "2017-06-15 00:36:26,287 - telegram.vendor.ptb_urllib3.urllib3.connectionpool - WARNING - Retrying (Retry(total=2, connect=None, read=None, redirect=None)) after connection broken by 'NewConnectionError('<telegram.vendor.ptb_urllib3.urllib3.connection.VerifiedHTTPSConnection object at 0x116a35be0>: Failed to establish a new connection: [Errno 8] nodename nor servname provided, or not known',)': /bot395861588:AAHXrGm2bD0VUDnVZLd6P45SzUas0e_SKNI/getUpdates\n",
      "2017-06-15 00:36:26,288 - telegram.vendor.ptb_urllib3.urllib3.connectionpool - WARNING - Retrying (Retry(total=1, connect=None, read=None, redirect=None)) after connection broken by 'NewConnectionError('<telegram.vendor.ptb_urllib3.urllib3.connection.VerifiedHTTPSConnection object at 0x116a35550>: Failed to establish a new connection: [Errno 8] nodename nor servname provided, or not known',)': /bot395861588:AAHXrGm2bD0VUDnVZLd6P45SzUas0e_SKNI/getUpdates\n",
      "2017-06-15 00:36:26,290 - telegram.vendor.ptb_urllib3.urllib3.connectionpool - WARNING - Retrying (Retry(total=0, connect=None, read=None, redirect=None)) after connection broken by 'NewConnectionError('<telegram.vendor.ptb_urllib3.urllib3.connection.VerifiedHTTPSConnection object at 0x116a35828>: Failed to establish a new connection: [Errno 8] nodename nor servname provided, or not known',)': /bot395861588:AAHXrGm2bD0VUDnVZLd6P45SzUas0e_SKNI/getUpdates\n",
      "2017-06-15 00:36:26,291 - telegram.ext.updater - ERROR - Error while getting Updates: urllib3 HTTPError HTTPSConnectionPool(host='api.telegram.org', port=443): Max retries exceeded with url: /bot395861588:AAHXrGm2bD0VUDnVZLd6P45SzUas0e_SKNI/getUpdates (Caused by NewConnectionError('<telegram.vendor.ptb_urllib3.urllib3.connection.VerifiedHTTPSConnection object at 0x116a35208>: Failed to establish a new connection: [Errno 8] nodename nor servname provided, or not known',))\n",
      "2017-06-15 00:36:26,292 - __main__ - WARNING - Update \"None\" caused error \"urllib3 HTTPError HTTPSConnectionPool(host='api.telegram.org', port=443): Max retries exceeded with url: /bot395861588:AAHXrGm2bD0VUDnVZLd6P45SzUas0e_SKNI/getUpdates (Caused by NewConnectionError('<telegram.vendor.ptb_urllib3.urllib3.connection.VerifiedHTTPSConnection object at 0x116a35208>: Failed to establish a new connection: [Errno 8] nodename nor servname provided, or not known',))\"\n",
      "2017-06-15 00:36:31,358 - telegram.vendor.ptb_urllib3.urllib3.connectionpool - WARNING - Retrying (Retry(total=2, connect=None, read=None, redirect=None)) after connection broken by 'NewConnectionError('<telegram.vendor.ptb_urllib3.urllib3.connection.VerifiedHTTPSConnection object at 0x116a35b38>: Failed to establish a new connection: [Errno 8] nodename nor servname provided, or not known',)': /bot395861588:AAHXrGm2bD0VUDnVZLd6P45SzUas0e_SKNI/getUpdates\n",
      "2017-06-15 00:36:31,359 - telegram.vendor.ptb_urllib3.urllib3.connectionpool - WARNING - Retrying (Retry(total=1, connect=None, read=None, redirect=None)) after connection broken by 'NewConnectionError('<telegram.vendor.ptb_urllib3.urllib3.connection.VerifiedHTTPSConnection object at 0x116a505c0>: Failed to establish a new connection: [Errno 8] nodename nor servname provided, or not known',)': /bot395861588:AAHXrGm2bD0VUDnVZLd6P45SzUas0e_SKNI/getUpdates\n",
      "2017-06-15 00:36:31,361 - telegram.vendor.ptb_urllib3.urllib3.connectionpool - WARNING - Retrying (Retry(total=0, connect=None, read=None, redirect=None)) after connection broken by 'NewConnectionError('<telegram.vendor.ptb_urllib3.urllib3.connection.VerifiedHTTPSConnection object at 0x116a50080>: Failed to establish a new connection: [Errno 8] nodename nor servname provided, or not known',)': /bot395861588:AAHXrGm2bD0VUDnVZLd6P45SzUas0e_SKNI/getUpdates\n",
      "2017-06-15 00:36:31,362 - telegram.ext.updater - ERROR - Error while getting Updates: urllib3 HTTPError HTTPSConnectionPool(host='api.telegram.org', port=443): Max retries exceeded with url: /bot395861588:AAHXrGm2bD0VUDnVZLd6P45SzUas0e_SKNI/getUpdates (Caused by NewConnectionError('<telegram.vendor.ptb_urllib3.urllib3.connection.VerifiedHTTPSConnection object at 0x116a50e48>: Failed to establish a new connection: [Errno 8] nodename nor servname provided, or not known',))\n",
      "2017-06-15 00:36:31,363 - __main__ - WARNING - Update \"None\" caused error \"urllib3 HTTPError HTTPSConnectionPool(host='api.telegram.org', port=443): Max retries exceeded with url: /bot395861588:AAHXrGm2bD0VUDnVZLd6P45SzUas0e_SKNI/getUpdates (Caused by NewConnectionError('<telegram.vendor.ptb_urllib3.urllib3.connection.VerifiedHTTPSConnection object at 0x116a50e48>: Failed to establish a new connection: [Errno 8] nodename nor servname provided, or not known',))\"\n",
      "2017-06-15 01:30:40,937 - telegram.ext.updater - ERROR - Error while getting Updates: Timed out\n",
      "2017-06-15 01:30:40,938 - __main__ - WARNING - Update \"None\" caused error \"Timed out\"\n",
      "2017-06-15 01:30:45,435 - telegram.vendor.ptb_urllib3.urllib3.connectionpool - WARNING - Retrying (Retry(total=2, connect=None, read=None, redirect=None)) after connection broken by 'NewConnectionError('<telegram.vendor.ptb_urllib3.urllib3.connection.VerifiedHTTPSConnection object at 0x116a507f0>: Failed to establish a new connection: [Errno 8] nodename nor servname provided, or not known',)': /bot395861588:AAHXrGm2bD0VUDnVZLd6P45SzUas0e_SKNI/getUpdates\n",
      "2017-06-15 01:30:45,437 - telegram.vendor.ptb_urllib3.urllib3.connectionpool - WARNING - Retrying (Retry(total=1, connect=None, read=None, redirect=None)) after connection broken by 'NewConnectionError('<telegram.vendor.ptb_urllib3.urllib3.connection.VerifiedHTTPSConnection object at 0x116a506a0>: Failed to establish a new connection: [Errno 8] nodename nor servname provided, or not known',)': /bot395861588:AAHXrGm2bD0VUDnVZLd6P45SzUas0e_SKNI/getUpdates\n",
      "2017-06-15 01:30:45,439 - telegram.vendor.ptb_urllib3.urllib3.connectionpool - WARNING - Retrying (Retry(total=0, connect=None, read=None, redirect=None)) after connection broken by 'NewConnectionError('<telegram.vendor.ptb_urllib3.urllib3.connection.VerifiedHTTPSConnection object at 0x116a502e8>: Failed to establish a new connection: [Errno 8] nodename nor servname provided, or not known',)': /bot395861588:AAHXrGm2bD0VUDnVZLd6P45SzUas0e_SKNI/getUpdates\n",
      "2017-06-15 01:30:45,441 - telegram.ext.updater - ERROR - Error while getting Updates: urllib3 HTTPError HTTPSConnectionPool(host='api.telegram.org', port=443): Max retries exceeded with url: /bot395861588:AAHXrGm2bD0VUDnVZLd6P45SzUas0e_SKNI/getUpdates (Caused by NewConnectionError('<telegram.vendor.ptb_urllib3.urllib3.connection.VerifiedHTTPSConnection object at 0x116a50c18>: Failed to establish a new connection: [Errno 8] nodename nor servname provided, or not known',))\n",
      "2017-06-15 01:30:45,443 - __main__ - WARNING - Update \"None\" caused error \"urllib3 HTTPError HTTPSConnectionPool(host='api.telegram.org', port=443): Max retries exceeded with url: /bot395861588:AAHXrGm2bD0VUDnVZLd6P45SzUas0e_SKNI/getUpdates (Caused by NewConnectionError('<telegram.vendor.ptb_urllib3.urllib3.connection.VerifiedHTTPSConnection object at 0x116a50c18>: Failed to establish a new connection: [Errno 8] nodename nor servname provided, or not known',))\"\n",
      "2017-06-15 01:30:47,007 - telegram.vendor.ptb_urllib3.urllib3.connectionpool - WARNING - Retrying (Retry(total=2, connect=None, read=None, redirect=None)) after connection broken by 'NewConnectionError('<telegram.vendor.ptb_urllib3.urllib3.connection.VerifiedHTTPSConnection object at 0x116a50eb8>: Failed to establish a new connection: [Errno 8] nodename nor servname provided, or not known',)': /bot395861588:AAHXrGm2bD0VUDnVZLd6P45SzUas0e_SKNI/getUpdates\n",
      "2017-06-15 01:30:47,008 - telegram.vendor.ptb_urllib3.urllib3.connectionpool - WARNING - Retrying (Retry(total=1, connect=None, read=None, redirect=None)) after connection broken by 'NewConnectionError('<telegram.vendor.ptb_urllib3.urllib3.connection.VerifiedHTTPSConnection object at 0x116a504e0>: Failed to establish a new connection: [Errno 8] nodename nor servname provided, or not known',)': /bot395861588:AAHXrGm2bD0VUDnVZLd6P45SzUas0e_SKNI/getUpdates\n",
      "2017-06-15 01:30:47,010 - telegram.vendor.ptb_urllib3.urllib3.connectionpool - WARNING - Retrying (Retry(total=0, connect=None, read=None, redirect=None)) after connection broken by 'NewConnectionError('<telegram.vendor.ptb_urllib3.urllib3.connection.VerifiedHTTPSConnection object at 0x116a50a90>: Failed to establish a new connection: [Errno 8] nodename nor servname provided, or not known',)': /bot395861588:AAHXrGm2bD0VUDnVZLd6P45SzUas0e_SKNI/getUpdates\n",
      "2017-06-15 01:30:47,012 - telegram.ext.updater - ERROR - Error while getting Updates: urllib3 HTTPError HTTPSConnectionPool(host='api.telegram.org', port=443): Max retries exceeded with url: /bot395861588:AAHXrGm2bD0VUDnVZLd6P45SzUas0e_SKNI/getUpdates (Caused by NewConnectionError('<telegram.vendor.ptb_urllib3.urllib3.connection.VerifiedHTTPSConnection object at 0x116a50940>: Failed to establish a new connection: [Errno 8] nodename nor servname provided, or not known',))\n",
      "2017-06-15 01:30:47,013 - __main__ - WARNING - Update \"None\" caused error \"urllib3 HTTPError HTTPSConnectionPool(host='api.telegram.org', port=443): Max retries exceeded with url: /bot395861588:AAHXrGm2bD0VUDnVZLd6P45SzUas0e_SKNI/getUpdates (Caused by NewConnectionError('<telegram.vendor.ptb_urllib3.urllib3.connection.VerifiedHTTPSConnection object at 0x116a50940>: Failed to establish a new connection: [Errno 8] nodename nor servname provided, or not known',))\"\n",
      "2017-06-15 01:30:49,264 - telegram.vendor.ptb_urllib3.urllib3.connectionpool - WARNING - Retrying (Retry(total=2, connect=None, read=None, redirect=None)) after connection broken by 'NewConnectionError('<telegram.vendor.ptb_urllib3.urllib3.connection.VerifiedHTTPSConnection object at 0x116a50be0>: Failed to establish a new connection: [Errno 8] nodename nor servname provided, or not known',)': /bot395861588:AAHXrGm2bD0VUDnVZLd6P45SzUas0e_SKNI/getUpdates\n",
      "2017-06-15 01:30:49,265 - telegram.vendor.ptb_urllib3.urllib3.connectionpool - WARNING - Retrying (Retry(total=1, connect=None, read=None, redirect=None)) after connection broken by 'NewConnectionError('<telegram.vendor.ptb_urllib3.urllib3.connection.VerifiedHTTPSConnection object at 0x116754e48>: Failed to establish a new connection: [Errno 8] nodename nor servname provided, or not known',)': /bot395861588:AAHXrGm2bD0VUDnVZLd6P45SzUas0e_SKNI/getUpdates\n",
      "2017-06-15 01:30:49,266 - telegram.vendor.ptb_urllib3.urllib3.connectionpool - WARNING - Retrying (Retry(total=0, connect=None, read=None, redirect=None)) after connection broken by 'NewConnectionError('<telegram.vendor.ptb_urllib3.urllib3.connection.VerifiedHTTPSConnection object at 0x1167540f0>: Failed to establish a new connection: [Errno 8] nodename nor servname provided, or not known',)': /bot395861588:AAHXrGm2bD0VUDnVZLd6P45SzUas0e_SKNI/getUpdates\n",
      "2017-06-15 01:30:49,271 - telegram.ext.updater - ERROR - Error while getting Updates: urllib3 HTTPError HTTPSConnectionPool(host='api.telegram.org', port=443): Max retries exceeded with url: /bot395861588:AAHXrGm2bD0VUDnVZLd6P45SzUas0e_SKNI/getUpdates (Caused by NewConnectionError('<telegram.vendor.ptb_urllib3.urllib3.connection.VerifiedHTTPSConnection object at 0x116754c18>: Failed to establish a new connection: [Errno 8] nodename nor servname provided, or not known',))\n",
      "2017-06-15 01:30:49,272 - __main__ - WARNING - Update \"None\" caused error \"urllib3 HTTPError HTTPSConnectionPool(host='api.telegram.org', port=443): Max retries exceeded with url: /bot395861588:AAHXrGm2bD0VUDnVZLd6P45SzUas0e_SKNI/getUpdates (Caused by NewConnectionError('<telegram.vendor.ptb_urllib3.urllib3.connection.VerifiedHTTPSConnection object at 0x116754c18>: Failed to establish a new connection: [Errno 8] nodename nor servname provided, or not known',))\"\n",
      "2017-06-15 01:30:52,653 - telegram.vendor.ptb_urllib3.urllib3.connectionpool - WARNING - Retrying (Retry(total=2, connect=None, read=None, redirect=None)) after connection broken by 'NewConnectionError('<telegram.vendor.ptb_urllib3.urllib3.connection.VerifiedHTTPSConnection object at 0x116754470>: Failed to establish a new connection: [Errno 8] nodename nor servname provided, or not known',)': /bot395861588:AAHXrGm2bD0VUDnVZLd6P45SzUas0e_SKNI/getUpdates\n",
      "2017-06-15 01:30:52,654 - telegram.vendor.ptb_urllib3.urllib3.connectionpool - WARNING - Retrying (Retry(total=1, connect=None, read=None, redirect=None)) after connection broken by 'NewConnectionError('<telegram.vendor.ptb_urllib3.urllib3.connection.VerifiedHTTPSConnection object at 0x116a501d0>: Failed to establish a new connection: [Errno 8] nodename nor servname provided, or not known',)': /bot395861588:AAHXrGm2bD0VUDnVZLd6P45SzUas0e_SKNI/getUpdates\n",
      "2017-06-15 01:30:52,655 - telegram.vendor.ptb_urllib3.urllib3.connectionpool - WARNING - Retrying (Retry(total=0, connect=None, read=None, redirect=None)) after connection broken by 'NewConnectionError('<telegram.vendor.ptb_urllib3.urllib3.connection.VerifiedHTTPSConnection object at 0x116a50278>: Failed to establish a new connection: [Errno 8] nodename nor servname provided, or not known',)': /bot395861588:AAHXrGm2bD0VUDnVZLd6P45SzUas0e_SKNI/getUpdates\n",
      "2017-06-15 01:30:52,657 - telegram.ext.updater - ERROR - Error while getting Updates: urllib3 HTTPError HTTPSConnectionPool(host='api.telegram.org', port=443): Max retries exceeded with url: /bot395861588:AAHXrGm2bD0VUDnVZLd6P45SzUas0e_SKNI/getUpdates (Caused by NewConnectionError('<telegram.vendor.ptb_urllib3.urllib3.connection.VerifiedHTTPSConnection object at 0x116a50390>: Failed to establish a new connection: [Errno 8] nodename nor servname provided, or not known',))\n",
      "2017-06-15 01:30:52,658 - __main__ - WARNING - Update \"None\" caused error \"urllib3 HTTPError HTTPSConnectionPool(host='api.telegram.org', port=443): Max retries exceeded with url: /bot395861588:AAHXrGm2bD0VUDnVZLd6P45SzUas0e_SKNI/getUpdates (Caused by NewConnectionError('<telegram.vendor.ptb_urllib3.urllib3.connection.VerifiedHTTPSConnection object at 0x116a50390>: Failed to establish a new connection: [Errno 8] nodename nor servname provided, or not known',))\"\n",
      "2017-06-15 01:30:57,731 - telegram.vendor.ptb_urllib3.urllib3.connectionpool - WARNING - Retrying (Retry(total=2, connect=None, read=None, redirect=None)) after connection broken by 'NewConnectionError('<telegram.vendor.ptb_urllib3.urllib3.connection.VerifiedHTTPSConnection object at 0x1100537b8>: Failed to establish a new connection: [Errno 8] nodename nor servname provided, or not known',)': /bot395861588:AAHXrGm2bD0VUDnVZLd6P45SzUas0e_SKNI/getUpdates\n",
      "2017-06-15 01:30:57,746 - telegram.vendor.ptb_urllib3.urllib3.connectionpool - WARNING - Retrying (Retry(total=1, connect=None, read=None, redirect=None)) after connection broken by 'NewConnectionError('<telegram.vendor.ptb_urllib3.urllib3.connection.VerifiedHTTPSConnection object at 0x116a504a8>: Failed to establish a new connection: [Errno 8] nodename nor servname provided, or not known',)': /bot395861588:AAHXrGm2bD0VUDnVZLd6P45SzUas0e_SKNI/getUpdates\n",
      "2017-06-15 01:30:57,747 - telegram.vendor.ptb_urllib3.urllib3.connectionpool - WARNING - Retrying (Retry(total=0, connect=None, read=None, redirect=None)) after connection broken by 'NewConnectionError('<telegram.vendor.ptb_urllib3.urllib3.connection.VerifiedHTTPSConnection object at 0x116a500b8>: Failed to establish a new connection: [Errno 8] nodename nor servname provided, or not known',)': /bot395861588:AAHXrGm2bD0VUDnVZLd6P45SzUas0e_SKNI/getUpdates\n",
      "2017-06-15 01:30:57,748 - telegram.ext.updater - ERROR - Error while getting Updates: urllib3 HTTPError HTTPSConnectionPool(host='api.telegram.org', port=443): Max retries exceeded with url: /bot395861588:AAHXrGm2bD0VUDnVZLd6P45SzUas0e_SKNI/getUpdates (Caused by NewConnectionError('<telegram.vendor.ptb_urllib3.urllib3.connection.VerifiedHTTPSConnection object at 0x116995eb8>: Failed to establish a new connection: [Errno 8] nodename nor servname provided, or not known',))\n",
      "2017-06-15 01:30:57,749 - __main__ - WARNING - Update \"None\" caused error \"urllib3 HTTPError HTTPSConnectionPool(host='api.telegram.org', port=443): Max retries exceeded with url: /bot395861588:AAHXrGm2bD0VUDnVZLd6P45SzUas0e_SKNI/getUpdates (Caused by NewConnectionError('<telegram.vendor.ptb_urllib3.urllib3.connection.VerifiedHTTPSConnection object at 0x116995eb8>: Failed to establish a new connection: [Errno 8] nodename nor servname provided, or not known',))\"\n",
      "2017-06-15 01:31:05,354 - telegram.vendor.ptb_urllib3.urllib3.connectionpool - WARNING - Retrying (Retry(total=2, connect=None, read=None, redirect=None)) after connection broken by 'NewConnectionError('<telegram.vendor.ptb_urllib3.urllib3.connection.VerifiedHTTPSConnection object at 0x116a50da0>: Failed to establish a new connection: [Errno 8] nodename nor servname provided, or not known',)': /bot395861588:AAHXrGm2bD0VUDnVZLd6P45SzUas0e_SKNI/getUpdates\n",
      "2017-06-15 01:31:05,355 - telegram.vendor.ptb_urllib3.urllib3.connectionpool - WARNING - Retrying (Retry(total=1, connect=None, read=None, redirect=None)) after connection broken by 'NewConnectionError('<telegram.vendor.ptb_urllib3.urllib3.connection.VerifiedHTTPSConnection object at 0x116a50400>: Failed to establish a new connection: [Errno 8] nodename nor servname provided, or not known',)': /bot395861588:AAHXrGm2bD0VUDnVZLd6P45SzUas0e_SKNI/getUpdates\n",
      "2017-06-15 01:31:05,356 - telegram.vendor.ptb_urllib3.urllib3.connectionpool - WARNING - Retrying (Retry(total=0, connect=None, read=None, redirect=None)) after connection broken by 'NewConnectionError('<telegram.vendor.ptb_urllib3.urllib3.connection.VerifiedHTTPSConnection object at 0x116a50ef0>: Failed to establish a new connection: [Errno 8] nodename nor servname provided, or not known',)': /bot395861588:AAHXrGm2bD0VUDnVZLd6P45SzUas0e_SKNI/getUpdates\n",
      "2017-06-15 01:31:05,358 - telegram.ext.updater - ERROR - Error while getting Updates: urllib3 HTTPError HTTPSConnectionPool(host='api.telegram.org', port=443): Max retries exceeded with url: /bot395861588:AAHXrGm2bD0VUDnVZLd6P45SzUas0e_SKNI/getUpdates (Caused by NewConnectionError('<telegram.vendor.ptb_urllib3.urllib3.connection.VerifiedHTTPSConnection object at 0x116a354e0>: Failed to establish a new connection: [Errno 8] nodename nor servname provided, or not known',))\n",
      "2017-06-15 01:31:05,359 - __main__ - WARNING - Update \"None\" caused error \"urllib3 HTTPError HTTPSConnectionPool(host='api.telegram.org', port=443): Max retries exceeded with url: /bot395861588:AAHXrGm2bD0VUDnVZLd6P45SzUas0e_SKNI/getUpdates (Caused by NewConnectionError('<telegram.vendor.ptb_urllib3.urllib3.connection.VerifiedHTTPSConnection object at 0x116a354e0>: Failed to establish a new connection: [Errno 8] nodename nor servname provided, or not known',))\"\n",
      "2017-06-15 02:10:17,897 - telegram.ext.updater - ERROR - Error while getting Updates: Timed out\n",
      "2017-06-15 02:10:17,897 - __main__ - WARNING - Update \"None\" caused error \"Timed out\"\n",
      "2017-06-15 02:10:24,730 - telegram.vendor.ptb_urllib3.urllib3.connectionpool - WARNING - Retrying (Retry(total=2, connect=None, read=None, redirect=None)) after connection broken by 'NewConnectionError('<telegram.vendor.ptb_urllib3.urllib3.connection.VerifiedHTTPSConnection object at 0x116a35208>: Failed to establish a new connection: [Errno 8] nodename nor servname provided, or not known',)': /bot395861588:AAHXrGm2bD0VUDnVZLd6P45SzUas0e_SKNI/getUpdates\n",
      "2017-06-15 02:10:24,732 - telegram.vendor.ptb_urllib3.urllib3.connectionpool - WARNING - Retrying (Retry(total=1, connect=None, read=None, redirect=None)) after connection broken by 'NewConnectionError('<telegram.vendor.ptb_urllib3.urllib3.connection.VerifiedHTTPSConnection object at 0x116a35d68>: Failed to establish a new connection: [Errno 8] nodename nor servname provided, or not known',)': /bot395861588:AAHXrGm2bD0VUDnVZLd6P45SzUas0e_SKNI/getUpdates\n",
      "2017-06-15 02:10:24,734 - telegram.vendor.ptb_urllib3.urllib3.connectionpool - WARNING - Retrying (Retry(total=0, connect=None, read=None, redirect=None)) after connection broken by 'NewConnectionError('<telegram.vendor.ptb_urllib3.urllib3.connection.VerifiedHTTPSConnection object at 0x116a35b38>: Failed to establish a new connection: [Errno 8] nodename nor servname provided, or not known',)': /bot395861588:AAHXrGm2bD0VUDnVZLd6P45SzUas0e_SKNI/getUpdates\n",
      "2017-06-15 02:10:24,742 - telegram.ext.updater - ERROR - Error while getting Updates: urllib3 HTTPError HTTPSConnectionPool(host='api.telegram.org', port=443): Max retries exceeded with url: /bot395861588:AAHXrGm2bD0VUDnVZLd6P45SzUas0e_SKNI/getUpdates (Caused by NewConnectionError('<telegram.vendor.ptb_urllib3.urllib3.connection.VerifiedHTTPSConnection object at 0x116a354a8>: Failed to establish a new connection: [Errno 8] nodename nor servname provided, or not known',))\n",
      "2017-06-15 02:10:24,743 - __main__ - WARNING - Update \"None\" caused error \"urllib3 HTTPError HTTPSConnectionPool(host='api.telegram.org', port=443): Max retries exceeded with url: /bot395861588:AAHXrGm2bD0VUDnVZLd6P45SzUas0e_SKNI/getUpdates (Caused by NewConnectionError('<telegram.vendor.ptb_urllib3.urllib3.connection.VerifiedHTTPSConnection object at 0x116a354a8>: Failed to establish a new connection: [Errno 8] nodename nor servname provided, or not known',))\"\n",
      "2017-06-15 02:10:26,248 - telegram.vendor.ptb_urllib3.urllib3.connectionpool - WARNING - Retrying (Retry(total=2, connect=None, read=None, redirect=None)) after connection broken by 'NewConnectionError('<telegram.vendor.ptb_urllib3.urllib3.connection.VerifiedHTTPSConnection object at 0x116a35828>: Failed to establish a new connection: [Errno 8] nodename nor servname provided, or not known',)': /bot395861588:AAHXrGm2bD0VUDnVZLd6P45SzUas0e_SKNI/getUpdates\n",
      "2017-06-15 02:10:26,249 - telegram.vendor.ptb_urllib3.urllib3.connectionpool - WARNING - Retrying (Retry(total=1, connect=None, read=None, redirect=None)) after connection broken by 'NewConnectionError('<telegram.vendor.ptb_urllib3.urllib3.connection.VerifiedHTTPSConnection object at 0x116a350b8>: Failed to establish a new connection: [Errno 8] nodename nor servname provided, or not known',)': /bot395861588:AAHXrGm2bD0VUDnVZLd6P45SzUas0e_SKNI/getUpdates\n",
      "2017-06-15 02:10:26,250 - telegram.vendor.ptb_urllib3.urllib3.connectionpool - WARNING - Retrying (Retry(total=0, connect=None, read=None, redirect=None)) after connection broken by 'NewConnectionError('<telegram.vendor.ptb_urllib3.urllib3.connection.VerifiedHTTPSConnection object at 0x116a2b908>: Failed to establish a new connection: [Errno 8] nodename nor servname provided, or not known',)': /bot395861588:AAHXrGm2bD0VUDnVZLd6P45SzUas0e_SKNI/getUpdates\n",
      "2017-06-15 02:10:26,252 - telegram.ext.updater - ERROR - Error while getting Updates: urllib3 HTTPError HTTPSConnectionPool(host='api.telegram.org', port=443): Max retries exceeded with url: /bot395861588:AAHXrGm2bD0VUDnVZLd6P45SzUas0e_SKNI/getUpdates (Caused by NewConnectionError('<telegram.vendor.ptb_urllib3.urllib3.connection.VerifiedHTTPSConnection object at 0x116a2b518>: Failed to establish a new connection: [Errno 8] nodename nor servname provided, or not known',))\n",
      "2017-06-15 02:10:26,253 - __main__ - WARNING - Update \"None\" caused error \"urllib3 HTTPError HTTPSConnectionPool(host='api.telegram.org', port=443): Max retries exceeded with url: /bot395861588:AAHXrGm2bD0VUDnVZLd6P45SzUas0e_SKNI/getUpdates (Caused by NewConnectionError('<telegram.vendor.ptb_urllib3.urllib3.connection.VerifiedHTTPSConnection object at 0x116a2b518>: Failed to establish a new connection: [Errno 8] nodename nor servname provided, or not known',))\"\n",
      "2017-06-15 02:10:28,508 - telegram.vendor.ptb_urllib3.urllib3.connectionpool - WARNING - Retrying (Retry(total=2, connect=None, read=None, redirect=None)) after connection broken by 'NewConnectionError('<telegram.vendor.ptb_urllib3.urllib3.connection.VerifiedHTTPSConnection object at 0x116a35f28>: Failed to establish a new connection: [Errno 8] nodename nor servname provided, or not known',)': /bot395861588:AAHXrGm2bD0VUDnVZLd6P45SzUas0e_SKNI/getUpdates\n",
      "2017-06-15 02:10:28,509 - telegram.vendor.ptb_urllib3.urllib3.connectionpool - WARNING - Retrying (Retry(total=1, connect=None, read=None, redirect=None)) after connection broken by 'NewConnectionError('<telegram.vendor.ptb_urllib3.urllib3.connection.VerifiedHTTPSConnection object at 0x116a2b5c0>: Failed to establish a new connection: [Errno 8] nodename nor servname provided, or not known',)': /bot395861588:AAHXrGm2bD0VUDnVZLd6P45SzUas0e_SKNI/getUpdates\n",
      "2017-06-15 02:10:28,511 - telegram.vendor.ptb_urllib3.urllib3.connectionpool - WARNING - Retrying (Retry(total=0, connect=None, read=None, redirect=None)) after connection broken by 'NewConnectionError('<telegram.vendor.ptb_urllib3.urllib3.connection.VerifiedHTTPSConnection object at 0x116a2bf28>: Failed to establish a new connection: [Errno 8] nodename nor servname provided, or not known',)': /bot395861588:AAHXrGm2bD0VUDnVZLd6P45SzUas0e_SKNI/getUpdates\n",
      "2017-06-15 02:10:28,515 - telegram.ext.updater - ERROR - Error while getting Updates: urllib3 HTTPError HTTPSConnectionPool(host='api.telegram.org', port=443): Max retries exceeded with url: /bot395861588:AAHXrGm2bD0VUDnVZLd6P45SzUas0e_SKNI/getUpdates (Caused by NewConnectionError('<telegram.vendor.ptb_urllib3.urllib3.connection.VerifiedHTTPSConnection object at 0x116a2bb00>: Failed to establish a new connection: [Errno 8] nodename nor servname provided, or not known',))\n",
      "2017-06-15 02:10:28,516 - __main__ - WARNING - Update \"None\" caused error \"urllib3 HTTPError HTTPSConnectionPool(host='api.telegram.org', port=443): Max retries exceeded with url: /bot395861588:AAHXrGm2bD0VUDnVZLd6P45SzUas0e_SKNI/getUpdates (Caused by NewConnectionError('<telegram.vendor.ptb_urllib3.urllib3.connection.VerifiedHTTPSConnection object at 0x116a2bb00>: Failed to establish a new connection: [Errno 8] nodename nor servname provided, or not known',))\"\n",
      "2017-06-15 02:10:31,894 - telegram.vendor.ptb_urllib3.urllib3.connectionpool - WARNING - Retrying (Retry(total=2, connect=None, read=None, redirect=None)) after connection broken by 'NewConnectionError('<telegram.vendor.ptb_urllib3.urllib3.connection.VerifiedHTTPSConnection object at 0x116a35ac8>: Failed to establish a new connection: [Errno 8] nodename nor servname provided, or not known',)': /bot395861588:AAHXrGm2bD0VUDnVZLd6P45SzUas0e_SKNI/getUpdates\n",
      "2017-06-15 02:10:31,895 - telegram.vendor.ptb_urllib3.urllib3.connectionpool - WARNING - Retrying (Retry(total=1, connect=None, read=None, redirect=None)) after connection broken by 'NewConnectionError('<telegram.vendor.ptb_urllib3.urllib3.connection.VerifiedHTTPSConnection object at 0x116a35cc0>: Failed to establish a new connection: [Errno 8] nodename nor servname provided, or not known',)': /bot395861588:AAHXrGm2bD0VUDnVZLd6P45SzUas0e_SKNI/getUpdates\n",
      "2017-06-15 02:10:31,896 - telegram.vendor.ptb_urllib3.urllib3.connectionpool - WARNING - Retrying (Retry(total=0, connect=None, read=None, redirect=None)) after connection broken by 'NewConnectionError('<telegram.vendor.ptb_urllib3.urllib3.connection.VerifiedHTTPSConnection object at 0x116a35cf8>: Failed to establish a new connection: [Errno 8] nodename nor servname provided, or not known',)': /bot395861588:AAHXrGm2bD0VUDnVZLd6P45SzUas0e_SKNI/getUpdates\n",
      "2017-06-15 02:10:31,898 - telegram.ext.updater - ERROR - Error while getting Updates: urllib3 HTTPError HTTPSConnectionPool(host='api.telegram.org', port=443): Max retries exceeded with url: /bot395861588:AAHXrGm2bD0VUDnVZLd6P45SzUas0e_SKNI/getUpdates (Caused by NewConnectionError('<telegram.vendor.ptb_urllib3.urllib3.connection.VerifiedHTTPSConnection object at 0x1100537b8>: Failed to establish a new connection: [Errno 8] nodename nor servname provided, or not known',))\n",
      "2017-06-15 02:10:31,899 - __main__ - WARNING - Update \"None\" caused error \"urllib3 HTTPError HTTPSConnectionPool(host='api.telegram.org', port=443): Max retries exceeded with url: /bot395861588:AAHXrGm2bD0VUDnVZLd6P45SzUas0e_SKNI/getUpdates (Caused by NewConnectionError('<telegram.vendor.ptb_urllib3.urllib3.connection.VerifiedHTTPSConnection object at 0x1100537b8>: Failed to establish a new connection: [Errno 8] nodename nor servname provided, or not known',))\"\n",
      "2017-06-15 02:10:36,964 - telegram.vendor.ptb_urllib3.urllib3.connectionpool - WARNING - Retrying (Retry(total=2, connect=None, read=None, redirect=None)) after connection broken by 'NewConnectionError('<telegram.vendor.ptb_urllib3.urllib3.connection.VerifiedHTTPSConnection object at 0x116a35e80>: Failed to establish a new connection: [Errno 8] nodename nor servname provided, or not known',)': /bot395861588:AAHXrGm2bD0VUDnVZLd6P45SzUas0e_SKNI/getUpdates\n",
      "2017-06-15 02:10:36,985 - telegram.vendor.ptb_urllib3.urllib3.connectionpool - WARNING - Retrying (Retry(total=1, connect=None, read=None, redirect=None)) after connection broken by 'NewConnectionError('<telegram.vendor.ptb_urllib3.urllib3.connection.VerifiedHTTPSConnection object at 0x116754cc0>: Failed to establish a new connection: [Errno 8] nodename nor servname provided, or not known',)': /bot395861588:AAHXrGm2bD0VUDnVZLd6P45SzUas0e_SKNI/getUpdates\n",
      "2017-06-15 02:10:36,986 - telegram.vendor.ptb_urllib3.urllib3.connectionpool - WARNING - Retrying (Retry(total=0, connect=None, read=None, redirect=None)) after connection broken by 'NewConnectionError('<telegram.vendor.ptb_urllib3.urllib3.connection.VerifiedHTTPSConnection object at 0x116754c18>: Failed to establish a new connection: [Errno 8] nodename nor servname provided, or not known',)': /bot395861588:AAHXrGm2bD0VUDnVZLd6P45SzUas0e_SKNI/getUpdates\n",
      "2017-06-15 02:10:36,995 - telegram.ext.updater - ERROR - Error while getting Updates: urllib3 HTTPError HTTPSConnectionPool(host='api.telegram.org', port=443): Max retries exceeded with url: /bot395861588:AAHXrGm2bD0VUDnVZLd6P45SzUas0e_SKNI/getUpdates (Caused by NewConnectionError('<telegram.vendor.ptb_urllib3.urllib3.connection.VerifiedHTTPSConnection object at 0x116a502b0>: Failed to establish a new connection: [Errno 8] nodename nor servname provided, or not known',))\n",
      "2017-06-15 02:10:36,996 - __main__ - WARNING - Update \"None\" caused error \"urllib3 HTTPError HTTPSConnectionPool(host='api.telegram.org', port=443): Max retries exceeded with url: /bot395861588:AAHXrGm2bD0VUDnVZLd6P45SzUas0e_SKNI/getUpdates (Caused by NewConnectionError('<telegram.vendor.ptb_urllib3.urllib3.connection.VerifiedHTTPSConnection object at 0x116a502b0>: Failed to establish a new connection: [Errno 8] nodename nor servname provided, or not known',))\"\n",
      "2017-06-16 02:49:35,298 - telegram.ext.updater - ERROR - Error while getting Updates: Timed out\n",
      "2017-06-16 02:49:35,506 - __main__ - WARNING - Update \"None\" caused error \"Timed out\"\n",
      "2017-06-16 05:24:36,592 - telegram.ext.updater - ERROR - Error while getting Updates: Timed out\n",
      "2017-06-16 05:24:36,740 - __main__ - WARNING - Update \"None\" caused error \"Timed out\"\n",
      "2017-06-16 05:24:57,834 - telegram.vendor.ptb_urllib3.urllib3.connectionpool - WARNING - Retrying (Retry(total=2, connect=None, read=None, redirect=None)) after connection broken by 'ConnectTimeoutError(<telegram.vendor.ptb_urllib3.urllib3.connection.VerifiedHTTPSConnection object at 0x116a507f0>, 'Connection to api.telegram.org timed out. (connect timeout=5.0)')': /bot395861588:AAHXrGm2bD0VUDnVZLd6P45SzUas0e_SKNI/getUpdates\n"
     ]
    }
   ],
   "source": [
    "if __name__ == '__main__':\n",
    "    main()"
   ]
  },
  {
   "cell_type": "code",
   "execution_count": null,
   "metadata": {
    "collapsed": true
   },
   "outputs": [],
   "source": []
  }
 ],
 "metadata": {
  "kernelspec": {
   "display_name": "Python 3",
   "language": "python",
   "name": "python3"
  },
  "language_info": {
   "codemirror_mode": {
    "name": "ipython",
    "version": 3
   },
   "file_extension": ".py",
   "mimetype": "text/x-python",
   "name": "python",
   "nbconvert_exporter": "python",
   "pygments_lexer": "ipython3",
   "version": "3.6.0"
  },
  "toc": {
   "colors": {
    "hover_highlight": "#DAA520",
    "running_highlight": "#FF0000",
    "selected_highlight": "#FFD700"
   },
   "moveMenuLeft": true,
   "nav_menu": {
    "height": "12px",
    "width": "252px"
   },
   "navigate_menu": true,
   "number_sections": true,
   "sideBar": true,
   "threshold": 4,
   "toc_cell": false,
   "toc_section_display": "block",
   "toc_window_display": false
  }
 },
 "nbformat": 4,
 "nbformat_minor": 2
}
